Workbook

Sheet Cover
B3: StartPad
B4: Operational Financial Model
B5: Thirty-six months · October 2026 to September 2029 · Egypt and Saudi Arabia · USD
B8: WHAT THIS IS
B9: A monthly operating model for three years, built directly on the volumes and the establishment in the StartPad business plan and on the channel structure in the go-to-market strategy.
B10: Every figure in the workbook is a formula. The only typed numbers are the inputs on the Assumptions, HR Model and Actuals sheets, which are shown in blue on a yellow fill.
B11: Change an input and the acquisition funnel, the revenue streams, the expense base, the three statements and every analysis sheet move with it.
B13: CONVENTIONS
B14: Blue figure on a yellow fill | C14: A typed input. Change these.
B15: Black figure | C15: A formula on this sheet.
B16: Green figure | C16: A link to another sheet.
B17: Red figure | C17: A check that must read nil.
B18: Lime band | C18: A headline result.
B20: CONTENTS
B21: 01 Cover | C21: This page — what the model is and how to read it
B22: 02 Dashboard | C22: The whole model on one page, with charts
B23: 03 Assumptions | C23: INPUT · every typed number: volumes, prices, acquisition, cost, revenue share, working capital
B24: 04 HR Model | C24: INPUT · eighteen roles, salaries and start months, monthly and annual
B25: 05 Actuals | C25: INPUT · the opening position and a grid to record each month as it closes
B26: 06 Capex | C26: INPUT · assets driven by new hires, plus shared and intangible assets
B27: 07 Acquisition | C27: PROCESS · offline and online channels, both funnels, 36 months
B28: 08 Revenue | C28: PROCESS · thirteen revenue lines across eight engines, 36 months
B29: 09 Expenses | C29: PROCESS · direct cost, revenue share to three parties, operating cost, 36 months
B30: 10 Depreciation | C30: PROCESS · straight-line depreciation and amortisation by asset class
B31: 11 Income Statement | C31: OUTPUT · three years to 30 September
B32: 12 Balance Sheet | C32: OUTPUT · three years, with the balance check
... B39: 19 Exit Strategy | C39: ANALYSIS · angel and venture returns, and the routes out
B41: Built from business_plan/model.py. Rebuild with: python scripts/build_financial_model_xlsx.py

Sheet Dashboard
A1: Dashboard
A2: The whole model on one page. Every figure is a link; nothing here is typed.
A5: HEADLINES
C6: Year 1 | D6: Year 2 | E6: Year 3
A7: Total revenue | C7: =Income_Statement!$C$9 -> 614990.61 | D7: =Income_Statement!$D$9 -> 2786041.1 | E7: =Income_Statement!$E$9 -> 6112588
A8: Gross profit | C8: =Income_Statement!$C$11 -> 388814.79 | D8: =Income_Statement!$D$11 -> 1856297 | E8: =Income_Statement!$E$11 -> 4043811.6
A9: EBITDA | C9: =Income_Statement!$C$13 -> -163865.33 | D9: =Income_Statement!$D$13 -> 641579.38 | E9: =Income_Statement!$E$13 -> 1869599.3
A10: Net profit | C10: =Income_Statement!$C$22 -> -215248.86 | D10: =Income_Statement!$D$22 -> 499107.71 | E10: =Income_Statement!$E$22 -> 1400468
A11: Cash at year end | C11: =KPIs!$C$39 -> 120154.62 | D11: =KPIs!$D$39 -> 511419.66 | E11: =KPIs!$E$39 -> 1903484.2
A12: Lowest cash in the year | C12: =KPIs!$C$40 -> 91108.322 | D12: =KPIs!$D$40 -> 113684.97 | E12: =KPIs!$E$40 -> 573923.8
A13: Employees at year end | C13: =KPIs!$C$13 -> 6 | D13: =KPIs!$D$13 -> 9 | E13: =KPIs!$E$13 -> 12
A14: Learners reached | C14: =KPIs!$C$11 -> 27014.11 | D14: =KPIs!$D$11 -> 83235.956 | E14: =KPIs!$E$11 -> 179961.34
A16: BALANCE SHEET AND CHECK
C17: At inception | D17: Year 1 | E17: Year 2 | F17: Year 3
A18: Total assets | C18: =Balance_Sheet!$C$11 -> 50000 | D18: =Balance_Sheet!$D$11 -> 585936.93 | E18: =Balance_Sheet!$E$11 -> 1394400 | F18: =Balance_Sheet!$F$11 -> 3551860.9
A19: CHECK — must be nil | C19: =Balance_Sheet!$C$24 -> 0 | D19: =Balance_Sheet!$D$24 -> 0 | E19: =Balance_Sheet!$E$24 -> 0 | F19: =Balance_Sheet!$F$24 -> 0
A41: HOW TO USE THIS WORKBOOK
A42: · Blue figures on a yellow fill are inputs. Change those and the whole model moves. Everything else is a formula.
A43: · The Assumptions sheet holds every typed number in the model. Nothing is typed on any process or output sheet.
A44: · Volume comes from the twelve-quarter plan in the business plan, split into months by the phasing weights on the Assumptions sheet.
A45: · The check line on the balance sheet must read nil in every column. If it does not, something upstream has been broken.

Sheet Assumptions
A1: Assumptions
A2: Every typed input in the model. Blue on yellow is an input you may change; black is a formula. Nothing elsewhere in the workbook is typed.
A5: 1 · TIMELINE AND BASIS
A6: Month 1 is October 2026, the Land quarter in the business plan. Year 1 runs Oct 2026 - Sep 2029 in three twelve-month blocks.
A7: Reporting currency | C7: USD
A8: Corporate tax rate (Egypt) | B8: Egyptian corporate income tax | C8: 0.225
A9: Tax paid in month of the following year | B9: Month 4 of the next financial year | C9: 4
A11: 2 · VOLUME DRIVERS — QUARTERLY, FROM THE BUSINESS PLAN
A12: These twelve quarters are the delivery plan. Monthly figures everywhere else are this quarter's volume split by the phasing weights below, so an annual total always ties back to the plan.
A13: Driver | B13: Unit | C13: Q4 2026 | D13: Q1 2027 | E13: Q2 2027 | F13: Q3 2027 | G13: Q4 2027 | H13: Q1 2028 | I13: Q2 2028 | J13: Q3 2028 | K13: Q4 2028 | L13: Q1 2029 | M13: Q2 2029 | N13: Q3 2029
A14: University cohorts — Egypt | B14: cohorts | C14: 0 | D14: 4 | E14: 7 | F14: 9 | G14: 11 | H14: 13 | I14: 15 | J14: 17 | K14: 20 | L14: 23 | M14: 25 | N14: 28
A15: University cohorts — Saudi Arabia | B15: cohorts | C15: 1 | D15: 2 | E15: 3 | F15: 4 | G15: 5 | H15: 5 | I15: 6 | J15: 6 | K15: 8 | L15: 9 | M15: 10 | N15: 11
A16: University pilot cohorts (unpaid) | B16: cohorts | C16: 4 | D16: 2 | E16: 1 | F16: 1 | G16: 1 | H16: 1 | I16: 1 | J16: 1 | K16: 1 | L16: 1 | M16: 1 | N16: 1
A17: Faculty licences sold | B17: licences | C17: 0 | D17: 0 | E17: 0 | F17: 1 | G17: 1 | H17: 1 | I17: 2 | J17: 2 | K17: 3 | L17: 3 | M17: 4 | N17: 4
A18: School cohorts | B18: cohorts | C18: 0 | D18: 0 | E18: 3 | F18: 6 | G18: 9 | H18: 12 | I18: 14 | J18: 16 | K18: 20 | L18: 24 | M18: 26 | N18: 30
A19: School licences sold | B19: licences | C19: 0 | D19: 0 | E19: 0 | F19: 0 | G19: 1 | H19: 1 | I19: 2 | J19: 2 | K19: 3 | L19: 3 | M19: 4 | N19: 4
A20: Technical and vocational cohorts | B20: cohorts | C20: 0 | D20: 0 | E20: 0 | F20: 2 | G20: 4 | H20: 5 | I20: 7 | J20: 8 | K20: 10 | L20: 12 | M20: 13 | N20: 15
A21: National initiative seats | B21: seats | C21: 0 | D21: 0 | E21: 0 | F21: 2000 | G21: 3000 | H21: 4000 | I21: 6000 | J21: 8000 | K21: 12000 | L21: 15000 | M21: 18000 | N21: 20000
A22: Train-the-trainer cohorts | B22: cohorts | C22: 0 | D22: 0 | E22: 0 | F22: 1 | G22: 1 | H22: 2 | I22: 2 | J22: 3 | K22: 4 | L22: 5 | M22: 5 | N22: 6
A23: NGO and donor programmes | B23: programmes | C23: 0 | D23: 0 | E23: 1 | F23: 1 | G23: 2 | H23: 2 | I23: 3 | J23: 3 | K23: 4 | L23: 4 | M23: 5 | N23: 5
A24: Sponsored competitions | B24: competitions | C24: 0 | D24: 1 | E24: 1 | F24: 2 | G24: 2 | H24: 2 | I24: 3 | J24: 3 | K24: 4 | L24: 4 | M24: 5 | N24: 5
A25: Corporate and CSR programmes | B25: programmes | C25: 0 | D25: 0 | E25: 0 | F25: 1 | G25: 1 | H25: 1 | I25: 1 | J25: 1 | K25: 2 | L25: 2 | M25: 2 | N25: 3
... A29: Certified delivery partner organisations | B29: cumulative at quarter end | C29: 0 | D29: 1 | E29: 2 | F29: 3 | G29: 5 | H29: 6 | I29: 8 | J29: 9 | K29: 10 | L29: 11 | M29: 12 | N29: 13
A31: Monthly phasing within a quarter | B31: month 1 / month 2 / month 3 of each quarter | C31: 0.3 | D31: 0.33 | E31: 0.37 | F31: =SUM(C31:E31) -> 1 | G31: must be 100%
A33: 3 · PRICING — BY YEAR
A34: University cohort — all-in programme fee | B34: 6 bootcamp days, seats, judging, cohort report | C34: 7500 | D34: 7900 | E34: 8300
A35: Faculty licence — annual | B35: faculty-wide, per year | C35: 25000 | D35: 25000 | E35: 25000
A36: School cohort | B36: 4 days, larger groups, employability frame | C36: 4500 | D36: 4700 | E36: 4900
A37: School licence — annual | C37: 12000 | D37: 12000 | E37: 12000
A38: Technical and vocational cohort | B38: 5 days | C38: 5000 | D38: 5200 | E38: 5400
A39: National initiative seat | B39: per participant, bulk provisioned | C39: 22 | D39: 20 | E39: 18
A40: Train-the-trainer cohort | C40: 12000 | D40: 12500 | E40: 13000
A41: NGO and donor programme | B41: multi-site, logframe reporting | C41: 35000 | D41: 38000 | E41: 40000
A42: Sponsored competition | B42: paid by the sponsor, not the organiser | C42: 28000 | D42: 32000 | E42: 36000
A43: Corporate and CSR programme | C43: 45000 | D43: 55000 | E43: 60000
A44: Programme and incubator seat | C44: 40 | D44: 42 | E44: 44
A45: Subscription — Pro, annual | C45: 59
A46: Subscription — Team, annual | C46: 179
A47: Share of new subscribers taking Team | C47: 0.25
A48: Subscription monthly churn | B48: of the active base, monthly | C48: 0.045
...

Sheet HR_Model
A1: HR Model
A2: Eighteen roles, each with a start month and a headcount per year. Payroll is computed monthly and summed annually; new hires drive the asset purchases on the Capex sheet.
A5: ESTABLISHMENT — INPUTS
A6: Role | B6: Function | C6: Start month | D6: Base monthly gross | E6: Headcount Y1 | F6: Headcount Y2 | G6: Headcount Y3
A7: Chief Executive Officer | B7: Leadership | C7: 1 | D7: 3000 | E7: 1 | F7: 1 | G7: 1
A8: Chief Technology Officer | B8: Leadership | C8: 1 | D8: 3000 | E8: 1 | F8: 1 | G8: 1
A9: Chief Operating Officer | B9: Leadership | C9: 25 | D9: 3200 | E9: 0 | F9: 0 | G9: 0
A10: Senior full-stack engineer | B10: Product and Engineering | C10: 1 | D10: 2400 | E10: 1 | F10: 2 | G10: 2
A11: AI and data engineer | B11: Product and Engineering | C11: 25 | D11: 2800 | E11: 0 | F11: 0 | G11: 0
A12: Product designer | B12: Product and Engineering | C12: 25 | D12: 1800 | E12: 0 | F12: 0 | G12: 0
A13: Head of Curriculum and Certification | B13: Curriculum and Delivery | C13: 1 | D13: 2400 | E13: 1 | F13: 1 | G13: 1
A14: Partner network manager | B14: Curriculum and Delivery | C14: 13 | D14: 2000 | E14: 0 | F14: 1 | G14: 1
A15: Programme delivery coordinator | B15: Curriculum and Delivery | C15: 25 | D15: 1500 | E15: 0 | F15: 0 | G15: 1
A16: Bilingual curriculum producer | B16: Curriculum and Delivery | C16: 25 | D16: 1300 | E16: 0 | F16: 0 | G16: 0
A17: Head of Partnerships — Egypt | B17: Institutional Partnerships | C17: 1 | D17: 2200 | E17: 1 | F17: 1 | G17: 1
A18: Country Manager — KSA (Riyadh) | B18: Institutional Partnerships | C18: 13 | D18: 5000 | E18: 0 | F18: 1 | G18: 1
... A24: Student success (bilingual) | B24: Growth and Content | C24: 25 | D24: 900 | E24: 0 | F24: 0 | G24: 0
A25: Total establishment | B25: the cap the business plan commits to | E25: =SUM(E7:E24) -> 6 | F25: =SUM(F7:F24) -> 9 | G25: =SUM(G7:G24) -> 12
A27: Employer burden on gross salary | B27: social insurance, end-of-service, medical | C27: 0.155
A28: Annual salary increment | B28: applied from year two | C28: 0.08
A30: MONTHLY PAYROLL — FULLY LOADED
A31: Line item | B31: Driver / source | C31: Oct 26 | D31: Nov 26 | E31: Dec 26 | F31: Jan 26 | G31: Feb 26 | H31: Mar 26 | I31: Apr 26 | J31: May 26 | K31: Jun 26 | L31: Jul 27 | M31: Aug 27 | N31: Sep 27 | O31: Oct 27 | P31: Nov 27 | Q31: Dec 27 | R31: Jan 27 | S31: Feb 27 | T31: Mar 27 | U31: Apr 27 | V31: May 27 | W31: Jun 27 | X31: Jul 28 | Y31: Aug 28 | Z31: Sep 28 | AA31: Oct 28 | AB31: Nov 28 | AC31: Dec 28 | AD31: Jan 28 | AE31: Feb 28 | AF31: Mar 28 | AG31: Apr 28 | AH31: May 28 | AI31: Jun 28 | AJ31: Jul 29 | AK31: Aug 29 | AL31: Sep 29 | AN31: YEAR 1 | AO31: YEAR 2 | AP31: YEAR 3
A32: Chief Executive Officer | B32: Leadership | C32: =IF(1<$C$7,0,$E$7*$D$7*(1+$C$27)*(1+$C$28)^0) -> 3465 | D32: =IF(2<$C$7,0,$E$7*$D$7*(1+$C$27)*(1+$C$28)^0) -> 3465 | E32: =IF(3<$C$7,0,$E$7*$D$7*(1+$C$27)*(1+$C$28)^0) -> 3465 | F32: =IF(4<$C$7,0,$E$7*$D$7*(1+$C$27)*(1+$C$28)^0) -> 3465 | G32: =IF(5<$C$7,0,$E$7*$D$7*(1+$C$27)*(1+$C$28)^0) -> 3465 | H32: =IF(6<$C$7,0,$E$7*$D$7*(1+$C$27)*(1+$C$28)^0) -> 3465 | I32: =IF(7<$C$7,0,$E$7*$D$7*(1+$C$27)*(1+$C$28)^0) -> 3465 | J32: =IF(8<$C$7,0,$E$7*$D$7*(1+$C$27)*(1+$C$28)^0) -> 3465 | K32: =IF(9<$C$7,0,$E$7*$D$7*(1+$C$27)*(1+$C$28)^0) -> 3465 | L32: =IF(10<$C$7,0,$E$7*$D$7*(1+$C$27)*(1+$C$28)^0) -> 3465 | M32: =IF(11<$C$7,0,$E$7*$D$7*(1+$C$27)*(1+$C$28)^0) -> 3465 | N32: =IF(12<$C$7,0,$E$7*$D$7*(1+$C$27)*(1+$C$28)^0) -> 3465 | O32: =IF(13<$C$7,0,$F$7*$D$7*(1+$C$27)*(1+$C$28)^1) -> 3742.2 | P32: =IF(14<$C$7,0,$F$7*$D$7*(1+$C$27)*(1+$C$28)^1) -> 3742.2 | Q32: =IF(15<$C$7,0,$F$7*$D$7*(1+$C$27)*(1+$C$28)^1) -> 3742.2 | R32: =IF(16<$C$7,0,$F$7*$D$7*(1+$C$27)*(1+$C$28)^1) -> 3742.2 | S32: =IF(17<$C$7,0,$F$7*$D$7*(1+$C$27)*(1+$C$28)^1) -> 3742.2 | T32: =IF(18<$C$7,0,$F$7*$D$7*(1+$C$27)*(1+$C$28)^1) -> 3742.2 | U32: =IF(19<$C$7,0,$F$7*$D$7*(1+$C$27)*(1+$C$28)^1) -> 3742.2 | V32: =IF(20<$C$7,0,$F$7*$D$7*(1+$C$27)*(1+$C$28)^1) -> 3742.2 | W32: =IF(21<$C$7,0,$F$7*$D$7*(1+$C$27)*(1+$C$28)^1) -> 3742.2 | X32: =IF(22<$C$7,0,$F$7*$D$7*(1+$C$27)*(1+$C$28)^1) -> 3742.2 | Y32: =IF(23<$C$7,0,$F$7*$D$7*(1+$C$27)*(1+$C$28)^1) -> 3742.2 | Z32: =IF(24<$C$7,0,$F$7*$D$7*(1+$C$27)*(1+$C$28)^1) -> 3742.2 | AA32: =IF(25<$C$7,0,$G$7*$D$7*(1+$C$27)*(1+$C$28)^2) -> 4041.576 | AB32: =IF(26<$C$7,0,$G$7*$D$7*(1+$C$27)*(1+$C$28)^2) -> 4041.576 | AC32: =IF(27<$C$7,0,$G$7*$D$7*(1+$C$27)*(1+$C$28)^2) -> 4041.576 | AD32: =IF(28<$C$7,0,$G$7*$D$7*(1+$C$27)*(1+$C$28)^2) -> 4041.576 | AE32: =IF(29<$C$7,0,$G$7*$D$7*(1+$C$27)*(1+$C$28)^2) -> 4041.576 | AF32: =IF(30<$C$7,0,$G$7*$D$7*(1+$C$27)*(1+$C$28)^2) -> 4041.576 | AG32: =IF(31<$C$7,0,$G$7*$D$7*(1+$C$27)*(1+$C$28)^2) -> 4041.576 | AH32: =IF(32<$C$7,0,$G$7*$D$7*(1+$C$27)*(1+$C$28)^2) -> 4041.576 | AI32: =IF(33<$C$7,0,$G$7*$D$7*(1+$C$27)*(1+$C$28)^2) -> 4041.576 | AJ32: =IF(34<$C$7,0,$G$7*$D$7*(1+$C$27)*(1+$C$28)^2) -> 4041.576 | AK32: =IF(35<$C$7,0,$G$7*$D$7*(1+$C$27)*(1+$C$28)^2) -> 4041.576 | AL32: =IF(36<$C$7,0,$G$7*$D$7*(1+$C$27)*(1+$C$28)^2) -> 4041.576 | AN32: =SUM(C32:N32) -> 41580 | AO32: =SUM(O32:Z32) -> 44906.4 | AP32: =SUM(AA32:AL32) -> 48498.912
A33: Chief Technology Officer | B33: Leadership | C33: =IF(1<$C$8,0,$E$8*$D$8*(1+$C$27)*(1+$C$28)^0) -> 3465 | D33: =IF(2<$C$8,0,$E$8*$D$8*(1+$C$27)*(1+$C$28)^0) -> 3465 | E33: =IF(3<$C$8,0,$E$8*$D$8*(1+$C$27)*(1+$C$28)^0) -> 3465 | F33: =IF(4<$C$8,0,$E$8*$D$8*(1+$C$27)*(1+$C$28)^0) -> 3465 | G33: =IF(5<$C$8,0,$E$8*$D$8*(1+$C$27)*(1+$C$28)^0) -> 3465 | H33: =IF(6<$C$8,0,$E$8*$D$8*(1+$C$27)*(1+$C$28)^0) -> 3465 | I33: =IF(7<$C$8,0,$E$8*$D$8*(1+$C$27)*(1+$C$28)^0) -> 3465 | J33: =IF(8<$C$8,0,$E$8*$D$8*(1+$C$27)*(1+$C$28)^0) -> 3465 | K33: =IF(9<$C$8,0,$E$8*$D$8*(1+$C$27)*(1+$C$28)^0) -> 3465 | L33: =IF(10<$C$8,0,$E$8*$D$8*(1+$C$27)*(1+$C$28)^0) -> 3465 | M33: =IF(11<$C$8,0,$E$8*$D$8*(1+$C$27)*(1+$C$28)^0) -> 3465 | N33: =IF(12<$C$8,0,$E$8*$D$8*(1+$C$27)*(1+$C$28)^0) -> 3465 | O33: =IF(13<$C$8,0,$F$8*$D$8*(1+$C$27)*(1+$C$28)^1) -> 3742.2 | P33: =IF(14<$C$8,0,$F$8*$D$8*(1+$C$27)*(1+$C$28)^1) -> 3742.2 | Q33: =IF(15<$C$8,0,$F$8*$D$8*(1+$C$27)*(1+$C$28)^1) -> 3742.2 | R33: =IF(16<$C$8,0,$F$8*$D$8*(1+$C$27)*(1+$C$28)^1) -> 3742.2 | S33: =IF(17<$C$8,0,$F$8*$D$8*(1+$C$27)*(1+$C$28)^1) -> 3742.2 | T33: =IF(18<$C$8,0,$F$8*$D$8*(1+$C$27)*(1+$C$28)^1) -> 3742.2 | U33: =IF(19<$C$8,0,$F$8*$D$8*(1+$C$27)*(1+$C$28)^1) -> 3742.2 | V33: =IF(20<$C$8,0,$F$8*$D$8*(1+$C$27)*(1+$C$28)^1) -> 3742.2 | W33: =IF(21<$C$8,0,$F$8*$D$8*(1+$C$27)*(1+$C$28)^1) -> 3742.2 | X33: =IF(22<$C$8,0,$F$8*$D$8*(1+$C$27)*(1+$C$28)^1) -> 3742.2 | Y33: =IF(23<$C$8,0,$F$8*$D$8*(1+$C$27)*(1+$C$28)^1) -> 3742.2 | Z33: =IF(24<$C$8,0,$F$8*$D$8*(1+$C$27)*(1+$C$28)^1) -> 3742.2 | AA33: =IF(25<$C$8,0,$G$8*$D$8*(1+$C$27)*(1+$C$28)^2) -> 4041.576 | AB33: =IF(26<$C$8,0,$G$8*$D$8*(1+$C$27)*(1+$C$28)^2) -> 4041.576 | AC33: =IF(27<$C$8,0,$G$8*$D$8*(1+$C$27)*(1+$C$28)^2) -> 4041.576 | AD33: =IF(28<$C$8,0,$G$8*$D$8*(1+$C$27)*(1+$C$28)^2) -> 4041.576 | AE33: =IF(29<$C$8,0,$G$8*$D$8*(1+$C$27)*(1+$C$28)^2) -> 4041.576 | AF33: =IF(30<$C$8,0,$G$8*$D$8*(1+$C$27)*(1+$C$28)^2) -> 4041.576 | AG33: =IF(31<$C$8,0,$G$8*$D$8*(1+$C$27)*(1+$C$28)^2) -> 4041.576 | AH33: =IF(32<$C$8,0,$G$8*$D$8*(1+$C$27)*(1+$C$28)^2) -> 4041.576 | AI33: =IF(33<$C$8,0,$G$8*$D$8*(1+$C$27)*(1+$C$28)^2) -> 4041.576 | AJ33: =IF(34<$C$8,0,$G$8*$D$8*(1+$C$27)*(1+$C$28)^2) -> 4041.576 | AK33: =IF(35<$C$8,0,$G$8*$D$8*(1+$C$27)*(1+$C$28)^2) -> 4041.576 | AL33: =IF(36<$C$8,0,$G$8*$D$8*(1+$C$27)*(1+$C$28)^2) -> 4041.576 | AN33: =SUM(C33:N33) -> 41580 | AO33: =SUM(O33:Z33) -> 44906.4 | AP33: =SUM(AA33:AL33) -> 48498.912
A34: Chief Operating Officer | B34: Leadership | C34: =IF(1<$C$9,0,$E$9*$D$9*(1+$C$27)*(1+$C$28)^0) -> 0 | D34: =IF(2<$C$9,0,$E$9*$D$9*(1+$C$27)*(1+$C$28)^0) -> 0 | E34: =IF(3<$C$9,0,$E$9*$D$9*(1+$C$27)*(1+$C$28)^0) -> 0 | F34: =IF(4<$C$9,0,$E$9*$D$9*(1+$C$27)*(1+$C$28)^0) -> 0 | G34: =IF(5<$C$9,0,$E$9*$D$9*(1+$C$27)*(1+$C$28)^0) -> 0 | H34: =IF(6<$C$9,0,$E$9*$D$9*(1+$C$27)*(1+$C$28)^0) -> 0 | I34: =IF(7<$C$9,0,$E$9*$D$9*(1+$C$27)*(1+$C$28)^0) -> 0 | J34: =IF(8<$C$9,0,$E$9*$D$9*(1+$C$27)*(1+$C$28)^0) -> 0 | K34: =IF(9<$C$9,0,$E$9*$D$9*(1+$C$27)*(1+$C$28)^0) -> 0 | L34: =IF(10<$C$9,0,$E$9*$D$9*(1+$C$27)*(1+$C$28)^0) -> 0 | M34: =IF(11<$C$9,0,$E$9*$D$9*(1+$C$27)*(1+$C$28)^0) -> 0 | N34: =IF(12<$C$9,0,$E$9*$D$9*(1+$C$27)*(1+$C$28)^0) -> 0 | O34: =IF(13<$C$9,0,$F$9*$D$9*(1+$C$27)*(1+$C$28)^1) -> 0 | P34: =IF(14<$C$9,0,$F$9*$D$9*(1+$C$27)*(1+$C$28)^1) -> 0 | Q34: =IF(15<$C$9,0,$F$9*$D$9*(1+$C$27)*(1+$C$28)^1) -> 0 | R34: =IF(16<$C$9,0,$F$9*$D$9*(1+$C$27)*(1+$C$28)^1) -> 0 | S34: =IF(17<$C$9,0,$F$9*$D$9*(1+$C$27)*(1+$C$28)^1) -> 0 | T34: =IF(18<$C$9,0,$F$9*$D$9*(1+$C$27)*(1+$C$28)^1) -> 0 | U34: =IF(19<$C$9,0,$F$9*$D$9*(1+$C$27)*(1+$C$28)^1) -> 0 | V34: =IF(20<$C$9,0,$F$9*$D$9*(1+$C$27)*(1+$C$28)^1) -> 0 | W34: =IF(21<$C$9,0,$F$9*$D$9*(1+$C$27)*(1+$C$28)^1) -> 0 | X34: =IF(22<$C$9,0,$F$9*$D$9*(1+$C$27)*(1+$C$28)^1) -> 0 | Y34: =IF(23<$C$9,0,$F$9*$D$9*(1+$C$27)*(1+$C$28)^1) -> 0 | Z34: =IF(24<$C$9,0,$F$9*$D$9*(1+$C$27)*(1+$C$28)^1) -> 0 | AA34: =IF(25<$C$9,0,$G$9*$D$9*(1+$C$27)*(1+$C$28)^2) -> 0 | AB34: =IF(26<$C$9,0,$G$9*$D$9*(1+$C$27)*(1+$C$28)^2) -> 0 | AC34: =IF(27<$C$9,0,$G$9*$D$9*(1+$C$27)*(1+$C$28)^2) -> 0 | AD34: =IF(28<$C$9,0,$G$9*$D$9*(1+$C$27)*(1+$C$28)^2) -> 0 | AE34: =IF(29<$C$9,0,$G$9*$D$9*(1+$C$27)*(1+$C$28)^2) -> 0 | AF34: =IF(30<$C$9,0,$G$9*$D$9*(1+$C$27)*(1+$C$28)^2) -> 0 | AG34: =IF(31<$C$9,0,$G$9*$D$9*(1+$C$27)*(1+$C$28)^2) -> 0 | AH34: =IF(32<$C$9,0,$G$9*$D$9*(1+$C$27)*(1+$C$28)^2) -> 0 | AI34: =IF(33<$C$9,0,$G$9*$D$9*(1+$C$27)*(1+$C$28)^2) -> 0 | AJ34: =IF(34<$C$9,0,$G$9*$D$9*(1+$C$27)*(1+$C$28)^2) -> 0 | AK34: =IF(35<$C$9,0,$G$9*$D$9*(1+$C$27)*(1+$C$28)^2) -> 0 | AL34: =IF(36<$C$9,0,$G$9*$D$9*(1+$C$27)*(1+$C$28)^2) -> 0 | AN34: =SUM(C34:N34) -> 0 | AO34: =SUM(O34:Z34) -> 0 | AP34: =SUM(AA34:AL34) -> 0
A35: Senior full-stack engineer | B35: Product and Engineering | C35: =IF(1<$C$10,0,$E$10*$D$10*(1+$C$27)*(1+$C$28)^0) -> 2772 | D35: =IF(2<$C$10,0,$E$10*$D$10*(1+$C$27)*(1+$C$28)^0) -> 2772 | E35: =IF(3<$C$10,0,$E$10*$D$10*(1+$C$27)*(1+$C$28)^0) -> 2772 | F35: =IF(4<$C$10,0,$E$10*$D$10*(1+$C$27)*(1+$C$28)^0) -> 2772 | G35: =IF(5<$C$10,0,$E$10*$D$10*(1+$C$27)*(1+$C$28)^0) -> 2772 | H35: =IF(6<$C$10,0,$E$10*$D$10*(1+$C$27)*(1+$C$28)^0) -> 2772 | I35: =IF(7<$C$10,0,$E$10*$D$10*(1+$C$27)*(1+$C$28)^0) -> 2772 | J35: =IF(8<$C$10,0,$E$10*$D$10*(1+$C$27)*(1+$C$28)^0) -> 2772 | K35: =IF(9<$C$10,0,$E$10*$D$10*(1+$C$27)*(1+$C$28)^0) -> 2772 | L35: =IF(10<$C$10,0,$E$10*$D$10*(1+$C$27)*(1+$C$28)^0) -> 2772 | M35: =IF(11<$C$10,0,$E$10*$D$10*(1+$C$27)*(1+$C$28)^0) -> 2772 | N35: =IF(12<$C$10,0,$E$10*$D$10*(1+$C$27)*(1+$C$28)^0) -> 2772 | O35: =IF(13<$C$10,0,$F$10*$D$10*(1+$C$27)*(1+$C$28)^1) -> 5987.52 | P35: =IF(14<$C$10,0,$F$10*$D$10*(1+$C$27)*(1+$C$28)^1) -> 5987.52 | Q35: =IF(15<$C$10,0,$F$10*$D$10*(1+$C$27)*(1+$C$28)^1) -> 5987.52 | R35: =IF(16<$C$10,0,$F$10*$D$10*(1+$C$27)*(1+$C$28)^1) -> 5987.52 | S35: =IF(17<$C$10,0,$F$10*$D$10*(1+$C$27)*(1+$C$28)^1) -> 5987.52 | T35: =IF(18<$C$10,0,$F$10*$D$10*(1+$C$27)*(1+$C$28)^1) -> 5987.52 | U35: =IF(19<$C$10,0,$F$10*$D$10*(1+$C$27)*(1+$C$28)^1) -> 5987.52 | V35: =IF(20<$C$10,0,$F$10*$D$10*(1+$C$27)*(1+$C$28)^1) -> 5987.52 | W35: =IF(21<$C$10,0,$F$10*$D$10*(1+$C$27)*(1+$C$28)^1) -> 5987.52 | X35: =IF(22<$C$10,0,$F$10*$D$10*(1+$C$27)*(1+$C$28)^1) -> 5987.52 | Y35: =IF(23<$C$10,0,$F$10*$D$10*(1+$C$27)*(1+$C$28)^1) -> 5987.52 | Z35: =IF(24<$C$10,0,$F$10*$D$10*(1+$C$27)*(1+$C$28)^1) -> 5987.52 | AA35: =IF(25<$C$10,0,$G$10*$D$10*(1+$C$27)*(1+$C$28)^2) -> 6466.5216 | AB35: =IF(26<$C$10,0,$G$10*$D$10*(1+$C$27)*(1+$C$28)^2) -> 6466.5216 | AC35: =IF(27<$C$10,0,$G$10*$D$10*(1+$C$27)*(1+$C$28)^2) -> 6466.5216 | AD35: =IF(28<$C$10,0,$G$10*$D$10*(1+$C$27)*(1+$C$28)^2) -> 6466.5216 | AE35: =IF(29<$C$10,0,$G$10*$D$10*(1+$C$27)*(1+$C$28)^2) -> 6466.5216 | AF35: =IF(30<$C$10,0,$G$10*$D$10*(1+$C$27)*(1+$C$28)^2) -> 6466.5216 | AG35: =IF(31<$C$10,0,$G$10*$D$10*(1+$C$27)*(1+$C$28)^2) -> 6466.5216 | AH35: =IF(32<$C$10,0,$G$10*$D$10*(1+$C$27)*(1+$C$28)^2) -> 6466.5216 | AI35: =IF(33<$C$10,0,$G$10*$D$10*(1+$C$27)*(1+$C$28)^2) -> 6466.5216 | AJ35: =IF(34<$C$10,0,$G$10*$D$10*(1+$C$27)*(1+$C$28)^2) -> 6466.5216 | AK35: =IF(35<$C$10,0,$G$10*$D$10*(1+$C$27)*(1+$C$28)^2) -> 6466.5216 | AL35: =IF(36<$C$10,0,$G$10*$D$10*(1+$C$27)*(1+$C$28)^2) -> 6466.5216 | AN35: =SUM(C35:N35) -> 33264 | AO35: =SUM(O35:Z35) -> 71850.24 | AP35: =SUM(AA35:AL35) -> 77598.259
A36: AI and data engineer | B36: Product and Engineering | C36: =IF(1<$C$11,0,$E$11*$D$11*(1+$C$27)*(1+$C$28)^0) -> 0 | D36: =IF(2<$C$11,0,$E$11*$D$11*(1+$C$27)*(1+$C$28)^0) -> 0 | E36: =IF(3<$C$11,0,$E$11*$D$11*(1+$C$27)*(1+$C$28)^0) -> 0 | F36: =IF(4<$C$11,0,$E$11*$D$11*(1+$C$27)*(1+$C$28)^0) -> 0 | G36: =IF(5<$C$11,0,$E$11*$D$11*(1+$C$27)*(1+$C$28)^0) -> 0 | H36: =IF(6<$C$11,0,$E$11*$D$11*(1+$C$27)*(1+$C$28)^0) -> 0 | I36: =IF(7<$C$11,0,$E$11*$D$11*(1+$C$27)*(1+$C$28)^0) -> 0 | J36: =IF(8<$C$11,0,$E$11*$D$11*(1+$C$27)*(1+$C$28)^0) -> 0 | K36: =IF(9<$C$11,0,$E$11*$D$11*(1+$C$27)*(1+$C$28)^0) -> 0 | L36: =IF(10<$C$11,0,$E$11*$D$11*(1+$C$27)*(1+$C$28)^0) -> 0 | M36: =IF(11<$C$11,0,$E$11*$D$11*(1+$C$27)*(1+$C$28)^0) -> 0 | N36: =IF(12<$C$11,0,$E$11*$D$11*(1+$C$27)*(1+$C$28)^0) -> 0 | O36: =IF(13<$C$11,0,$F$11*$D$11*(1+$C$27)*(1+$C$28)^1) -> 0 | P36: =IF(14<$C$11,0,$F$11*$D$11*(1+$C$27)*(1+$C$28)^1) -> 0 | Q36: =IF(15<$C$11,0,$F$11*$D$11*(1+$C$27)*(1+$C$28)^1) -> 0 | R36: =IF(16<$C$11,0,$F$11*$D$11*(1+$C$27)*(1+$C$28)^1) -> 0 | S36: =IF(17<$C$11,0,$F$11*$D$11*(1+$C$27)*(1+$C$28)^1) -> 0 | T36: =IF(18<$C$11,0,$F$11*$D$11*(1+$C$27)*(1+$C$28)^1) -> 0 | U36: =IF(19<$C$11,0,$F$11*$D$11*(1+$C$27)*(1+$C$28)^1) -> 0 | V36: =IF(20<$C$11,0,$F$11*$D$11*(1+$C$27)*(1+$C$28)^1) -> 0 | W36: =IF(21<$C$11,0,$F$11*$D$11*(1+$C$27)*(1+$C$28)^1) -> 0 | X36: =IF(22<$C$11,0,$F$11*$D$11*(1+$C$27)*(1+$C$28)^1) -> 0 | Y36: =IF(23<$C$11,0,$F$11*$D$11*(1+$C$27)*(1+$C$28)^1) -> 0 | Z36: =IF(24<$C$11,0,$F$11*$D$11*(1+$C$27)*(1+$C$28)^1) -> 0 | AA36: =IF(25<$C$11,0,$G$11*$D$11*(1+$C$27)*(1+$C$28)^2) -> 0 | AB36: =IF(26<$C$11,0,$G$11*$D$11*(1+$C$27)*(1+$C$28)^2) -> 0 | AC36: =IF(27<$C$11,0,$G$11*$D$11*(1+$C$27)*(1+$C$28)^2) -> 0 | AD36: =IF(28<$C$11,0,$G$11*$D$11*(1+$C$27)*(1+$C$28)^2) -> 0 | AE36: =IF(29<$C$11,0,$G$11*$D$11*(1+$C$27)*(1+$C$28)^2) -> 0 | AF36: =IF(30<$C$11,0,$G$11*$D$11*(1+$C$27)*(1+$C$28)^2) -> 0 | AG36: =IF(31<$C$11,0,$G$11*$D$11*(1+$C$27)*(1+$C$28)^2) -> 0 | AH36: =IF(32<$C$11,0,$G$11*$D$11*(1+$C$27)*(1+$C$28)^2) -> 0 | AI36: =IF(33<$C$11,0,$G$11*$D$11*(1+$C$27)*(1+$C$28)^2) -> 0 | AJ36: =IF(34<$C$11,0,$G$11*$D$11*(1+$C$27)*(1+$C$28)^2) -> 0 | AK36: =IF(35<$C$11,0,$G$11*$D$11*(1+$C$27)*(1+$C$28)^2) -> 0 | AL36: =IF(36<$C$11,0,$G$11*$D$11*(1+$C$27)*(1+$C$28)^2) -> 0 | AN36: =SUM(C36:N36) -> 0 | AO36: =SUM(O36:Z36) -> 0 | AP36: =SUM(AA36:AL36) -> 0
A37: Product designer | B37: Product and Engineering | C37: =IF(1<$C$12,0,$E$12*$D$12*(1+$C$27)*(1+$C$28)^0) -> 0 | D37: =IF(2<$C$12,0,$E$12*$D$12*(1+$C$27)*(1+$C$28)^0) -> 0 | E37: =IF(3<$C$12,0,$E$12*$D$12*(1+$C$27)*(1+$C$28)^0) -> 0 | F37: =IF(4<$C$12,0,$E$12*$D$12*(1+$C$27)*(1+$C$28)^0) -> 0 | G37: =IF(5<$C$12,0,$E$12*$D$12*(1+$C$27)*(1+$C$28)^0) -> 0 | H37: =IF(6<$C$12,0,$E$12*$D$12*(1+$C$27)*(1+$C$28)^0) -> 0 | I37: =IF(7<$C$12,0,$E$12*$D$12*(1+$C$27)*(1+$C$28)^0) -> 0 | J37: =IF(8<$C$12,0,$E$12*$D$12*(1+$C$27)*(1+$C$28)^0) -> 0 | K37: =IF(9<$C$12,0,$E$12*$D$12*(1+$C$27)*(1+$C$28)^0) -> 0 | L37: =IF(10<$C$12,0,$E$12*$D$12*(1+$C$27)*(1+$C$28)^0) -> 0 | M37: =IF(11<$C$12,0,$E$12*$D$12*(1+$C$27)*(1+$C$28)^0) -> 0 | N37: =IF(12<$C$12,0,$E$12*$D$12*(1+$C$27)*(1+$C$28)^0) -> 0 | O37: =IF(13<$C$12,0,$F$12*$D$12*(1+$C$27)*(1+$C$28)^1) -> 0 | P37: =IF(14<$C$12,0,$F$12*$D$12*(1+$C$27)*(1+$C$28)^1) -> 0 | Q37: =IF(15<$C$12,0,$F$12*$D$12*(1+$C$27)*(1+$C$28)^1) -> 0 | R37: =IF(16<$C$12,0,$F$12*$D$12*(1+$C$27)*(1+$C$28)^1) -> 0 | S37: =IF(17<$C$12,0,$F$12*$D$12*(1+$C$27)*(1+$C$28)^1) -> 0 | T37: =IF(18<$C$12,0,$F$12*$D$12*(1+$C$27)*(1+$C$28)^1) -> 0 | U37: =IF(19<$C$12,0,$F$12*$D$12*(1+$C$27)*(1+$C$28)^1) -> 0 | V37: =IF(20<$C$12,0,$F$12*$D$12*(1+$C$27)*(1+$C$28)^1) -> 0 | W37: =IF(21<$C$12,0,$F$12*$D$12*(1+$C$27)*(1+$C$28)^1) -> 0 | X37: =IF(22<$C$12,0,$F$12*$D$12*(1+$C$27)*(1+$C$28)^1) -> 0 | Y37: =IF(23<$C$12,0,$F$12*$D$12*(1+$C$27)*(1+$C$28)^1) -> 0 | Z37: =IF(24<$C$12,0,$F$12*$D$12*(1+$C$27)*(1+$C$28)^1) -> 0 | AA37: =IF(25<$C$12,0,$G$12*$D$12*(1+$C$27)*(1+$C$28)^2) -> 0 | AB37: =IF(26<$C$12,0,$G$12*$D$12*(1+$C$27)*(1+$C$28)^2) -> 0 | AC37: =IF(27<$C$12,0,$G$12*$D$12*(1+$C$27)*(1+$C$28)^2) -> 0 | AD37: =IF(28<$C$12,0,$G$12*$D$12*(1+$C$27)*(1+$C$28)^2) -> 0 | AE37: =IF(29<$C$12,0,$G$12*$D$12*(1+$C$27)*(1+$C$28)^2) -> 0 | AF37: =IF(30<$C$12,0,$G$12*$D$12*(1+$C$27)*(1+$C$28)^2) -> 0 | AG37: =IF(31<$C$12,0,$G$12*$D$12*(1+$C$27)*(1+$C$28)^2) -> 0 | AH37: =IF(32<$C$12,0,$G$12*$D$12*(1+$C$27)*(1+$C$28)^2) -> 0 | AI37: =IF(33<$C$12,0,$G$12*$D$12*(1+$C$27)*(1+$C$28)^2) -> 0 | AJ37: =IF(34<$C$12,0,$G$12*$D$12*(1+$C$27)*(1+$C$28)^2) -> 0 | AK37: =IF(35<$C$12,0,$G$12*$D$12*(1+$C$27)*(1+$C$28)^2) -> 0 | AL37: =IF(36<$C$12,0,$G$12*$D$12*(1+$C$27)*(1+$C$28)^2) -> 0 | AN37: =SUM(C37:N37) -> 0 | AO37: =SUM(O37:Z37) -> 0 | AP37: =SUM(AA37:AL37) -> 0
A38: Head of Curriculum and Certification | B38: Curriculum and Delivery | C38: =IF(1<$C$13,0,$E$13*$D$13*(1+$C$27)*(1+$C$28)^0) -> 2772 | D38: =IF(2<$C$13,0,$E$13*$D$13*(1+$C$27)*(1+$C$28)^0) -> 2772 | E38: =IF(3<$C$13,0,$E$13*$D$13*(1+$C$27)*(1+$C$28)^0) -> 2772 | F38: =IF(4<$C$13,0,$E$13*$D$13*(1+$C$27)*(1+$C$28)^0) -> 2772 | G38: =IF(5<$C$13,0,$E$13*$D$13*(1+$C$27)*(1+$C$28)^0) -> 2772 | H38: =IF(6<$C$13,0,$E$13*$D$13*(1+$C$27)*(1+$C$28)^0) -> 2772 | I38: =IF(7<$C$13,0,$E$13*$D$13*(1+$C$27)*(1+$C$28)^0) -> 2772 | J38: =IF(8<$C$13,0,$E$13*$D$13*(1+$C$27)*(1+$C$28)^0) -> 2772 | K38: =IF(9<$C$13,0,$E$13*$D$13*(1+$C$27)*(1+$C$28)^0) -> 2772 | L38: =IF(10<$C$13,0,$E$13*$D$13*(1+$C$27)*(1+$C$28)^0) -> 2772 | M38: =IF(11<$C$13,0,$E$13*$D$13*(1+$C$27)*(1+$C$28)^0) -> 2772 | N38: =IF(12<$C$13,0,$E$13*$D$13*(1+$C$27)*(1+$C$28)^0) -> 2772 | O38: =IF(13<$C$13,0,$F$13*$D$13*(1+$C$27)*(1+$C$28)^1) -> 2993.76 | P38: =IF(14<$C$13,0,$F$13*$D$13*(1+$C$27)*(1+$C$28)^1) -> 2993.76 | Q38: =IF(15<$C$13,0,$F$13*$D$13*(1+$C$27)*(1+$C$28)^1) -> 2993.76 | R38: =IF(16<$C$13,0,$F$13*$D$13*(1+$C$27)*(1+$C$28)^1) -> 2993.76 | S38: =IF(17<$C$13,0,$F$13*$D$13*(1+$C$27)*(1+$C$28)^1) -> 2993.76 | T38: =IF(18<$C$13,0,$F$13*$D$13*(1+$C$27)*(1+$C$28)^1) -> 2993.76 | U38: =IF(19<$C$13,0,$F$13*$D$13*(1+$C$27)*(1+$C$28)^1) -> 2993.76 | V38: =IF(20<$C$13,0,$F$13*$D$13*(1+$C$27)*(1+$C$28)^1) -> 2993.76 | W38: =IF(21<$C$13,0,$F$13*$D$13*(1+$C$27)*(1+$C$28)^1) -> 2993.76 | X38: =IF(22<$C$13,0,$F$13*$D$13*(1+$C$27)*(1+$C$28)^1) -> 2993.76 | Y38: =IF(23<$C$13,0,$F$13*$D$13*(1+$C$27)*(1+$C$28)^1) -> 2993.76 | Z38: =IF(24<$C$13,0,$F$13*$D$13*(1+$C$27)*(1+$C$28)^1) -> 2993.76 | AA38: =IF(25<$C$13,0,$G$13*$D$13*(1+$C$27)*(1+$C$28)^2) -> 3233.2608 | AB38: =IF(26<$C$13,0,$G$13*$D$13*(1+$C$27)*(1+$C$28)^2) -> 3233.2608 | AC38: =IF(27<$C$13,0,$G$13*$D$13*(1+$C$27)*(1+$C$28)^2) -> 3233.2608 | AD38: =IF(28<$C$13,0,$G$13*$D$13*(1+$C$27)*(1+$C$28)^2) -> 3233.2608 | AE38: =IF(29<$C$13,0,$G$13*$D$13*(1+$C$27)*(1+$C$28)^2) -> 3233.2608 | AF38: =IF(30<$C$13,0,$G$13*$D$13*(1+$C$27)*(1+$C$28)^2) -> 3233.2608 | AG38: =IF(31<$C$13,0,$G$13*$D$13*(1+$C$27)*(1+$C$28)^2) -> 3233.2608 | AH38: =IF(32<$C$13,0,$G$13*$D$13*(1+$C$27)*(1+$C$28)^2) -> 3233.2608 | AI38: =IF(33<$C$13,0,$G$13*$D$13*(1+$C$27)*(1+$C$28)^2) -> 3233.2608 | AJ38: =IF(34<$C$13,0,$G$13*$D$13*(1+$C$27)*(1+$C$28)^2) -> 3233.2608 | AK38: =IF(35<$C$13,0,$G$13*$D$13*(1+$C$27)*(1+$C$28)^2) -> 3233.2608 | AL38: =IF(36<$C$13,0,$G$13*$D$13*(1+$C$27)*(1+$C$28)^2) -> 3233.2608 | AN38: =SUM(C38:N38) -> 33264 | AO38: =SUM(O38:Z38) -> 35925.12 | AP38: =SUM(AA38:AL38) -> 38799.13
A39: Partner network manager | B39: Curriculum and Delivery | C39: =IF(1<$C$14,0,$E$14*$D$14*(1+$C$27)*(1+$C$28)^0) -> 0 | D39: =IF(2<$C$14,0,$E$14*$D$14*(1+$C$27)*(1+$C$28)^0) -> 0 | E39: =IF(3<$C$14,0,$E$14*$D$14*(1+$C$27)*(1+$C$28)^0) -> 0 | F39: =IF(4<$C$14,0,$E$14*$D$14*(1+$C$27)*(1+$C$28)^0) -> 0 | G39: =IF(5<$C$14,0,$E$14*$D$14*(1+$C$27)*(1+$C$28)^0) -> 0 | H39: =IF(6<$C$14,0,$E$14*$D$14*(1+$C$27)*(1+$C$28)^0) -> 0 | I39: =IF(7<$C$14,0,$E$14*$D$14*(1+$C$27)*(1+$C$28)^0) -> 0 | J39: =IF(8<$C$14,0,$E$14*$D$14*(1+$C$27)*(1+$C$28)^0) -> 0 | K39: =IF(9<$C$14,0,$E$14*$D$14*(1+$C$27)*(1+$C$28)^0) -> 0 | L39: =IF(10<$C$14,0,$E$14*$D$14*(1+$C$27)*(1+$C$28)^0) -> 0 | M39: =IF(11<$C$14,0,$E$14*$D$14*(1+$C$27)*(1+$C$28)^0) -> 0 | N39: =IF(12<$C$14,0,$E$14*$D$14*(1+$C$27)*(1+$C$28)^0) -> 0 | O39: =IF(13<$C$14,0,$F$14*$D$14*(1+$C$27)*(1+$C$28)^1) -> 2494.8 | P39: =IF(14<$C$14,0,$F$14*$D$14*(1+$C$27)*(1+$C$28)^1) -> 2494.8 | Q39: =IF(15<$C$14,0,$F$14*$D$14*(1+$C$27)*(1+$C$28)^1) -> 2494.8 | R39: =IF(16<$C$14,0,$F$14*$D$14*(1+$C$27)*(1+$C$28)^1) -> 2494.8 | S39: =IF(17<$C$14,0,$F$14*$D$14*(1+$C$27)*(1+$C$28)^1) -> 2494.8 | T39: =IF(18<$C$14,0,$F$14*$D$14*(1+$C$27)*(1+$C$28)^1) -> 2494.8 | U39: =IF(19<$C$14,0,$F$14*$D$14*(1+$C$27)*(1+$C$28)^1) -> 2494.8 | V39: =IF(20<$C$14,0,$F$14*$D$14*(1+$C$27)*(1+$C$28)^1) -> 2494.8 | W39: =IF(21<$C$14,0,$F$14*$D$14*(1+$C$27)*(1+$C$28)^1) -> 2494.8 | X39: =IF(22<$C$14,0,$F$14*$D$14*(1+$C$27)*(1+$C$28)^1) -> 2494.8 | Y39: =IF(23<$C$14,0,$F$14*$D$14*(1+$C$27)*(1+$C$28)^1) -> 2494.8 | Z39: =IF(24<$C$14,0,$F$14*$D$14*(1+$C$27)*(1+$C$28)^1) -> 2494.8 | AA39: =IF(25<$C$14,0,$G$14*$D$14*(1+$C$27)*(1+$C$28)^2) -> 2694.384 | AB39: =IF(26<$C$14,0,$G$14*$D$14*(1+$C$27)*(1+$C$28)^2) -> 2694.384 | AC39: =IF(27<$C$14,0,$G$14*$D$14*(1+$C$27)*(1+$C$28)^2) -> 2694.384 | AD39: =IF(28<$C$14,0,$G$14*$D$14*(1+$C$27)*(1+$C$28)^2) -> 2694.384 | AE39: =IF(29<$C$14,0,$G$14*$D$14*(1+$C$27)*(1+$C$28)^2) -> 2694.384 | AF39: =IF(30<$C$14,0,$G$14*$D$14*(1+$C$27)*(1+$C$28)^2) -> 2694.384 | AG39: =IF(31<$C$14,0,$G$14*$D$14*(1+$C$27)*(1+$C$28)^2) -> 2694.384 | AH39: =IF(32<$C$14,0,$G$14*$D$14*(1+$C$27)*(1+$C$28)^2) -> 2694.384 | AI39: =IF(33<$C$14,0,$G$14*$D$14*(1+$C$27)*(1+$C$28)^2) -> 2694.384 | AJ39: =IF(34<$C$14,0,$G$14*$D$14*(1+$C$27)*(1+$C$28)^2) -> 2694.384 | AK39: =IF(35<$C$14,0,$G$14*$D$14*(1+$C$27)*(1+$C$28)^2) -> 2694.384 | AL39: =IF(36<$C$14,0,$G$14*$D$14*(1+$C$27)*(1+$C$28)^2) -> 2694.384 | AN39: =SUM(C39:N39) -> 0 | AO39: =SUM(O39:Z39) -> 29937.6 | AP39: =SUM(AA39:AL39) -> 32332.608
A40: Programme delivery coordinator | B40: Curriculum and Delivery | C40: =IF(1<$C$15,0,$E$15*$D$15*(1+$C$27)*(1+$C$28)^0) -> 0 | D40: =IF(2<$C$15,0,$E$15*$D$15*(1+$C$27)*(1+$C$28)^0) -> 0 | E40: =IF(3<$C$15,0,$E$15*$D$15*(1+$C$27)*(1+$C$28)^0) -> 0 | F40: =IF(4<$C$15,0,$E$15*$D$15*(1+$C$27)*(1+$C$28)^0) -> 0 | G40: =IF(5<$C$15,0,$E$15*$D$15*(1+$C$27)*(1+$C$28)^0) -> 0 | H40: =IF(6<$C$15,0,$E$15*$D$15*(1+$C$27)*(1+$C$28)^0) -> 0 | I40: =IF(7<$C$15,0,$E$15*$D$15*(1+$C$27)*(1+$C$28)^0) -> 0 | J40: =IF(8<$C$15,0,$E$15*$D$15*(1+$C$27)*(1+$C$28)^0) -> 0 | K40: =IF(9<$C$15,0,$E$15*$D$15*(1+$C$27)*(1+$C$28)^0) -> 0 | L40: =IF(10<$C$15,0,$E$15*$D$15*(1+$C$27)*(1+$C$28)^0) -> 0 | M40: =IF(11<$C$15,0,$E$15*$D$15*(1+$C$27)*(1+$C$28)^0) -> 0 | N40: =IF(12<$C$15,0,$E$15*$D$15*(1+$C$27)*(1+$C$28)^0) -> 0 | O40: =IF(13<$C$15,0,$F$15*$D$15*(1+$C$27)*(1+$C$28)^1) -> 0 | P40: =IF(14<$C$15,0,$F$15*$D$15*(1+$C$27)*(1+$C$28)^1) -> 0 | Q40: =IF(15<$C$15,0,$F$15*$D$15*(1+$C$27)*(1+$C$28)^1) -> 0 | R40: =IF(16<$C$15,0,$F$15*$D$15*(1+$C$27)*(1+$C$28)^1) -> 0 | S40: =IF(17<$C$15,0,$F$15*$D$15*(1+$C$27)*(1+$C$28)^1) -> 0 | T40: =IF(18<$C$15,0,$F$15*$D$15*(1+$C$27)*(1+$C$28)^1) -> 0 | U40: =IF(19<$C$15,0,$F$15*$D$15*(1+$C$27)*(1+$C$28)^1) -> 0 | V40: =IF(20<$C$15,0,$F$15*$D$15*(1+$C$27)*(1+$C$28)^1) -> 0 | W40: =IF(21<$C$15,0,$F$15*$D$15*(1+$C$27)*(1+$C$28)^1) -> 0 | X40: =IF(22<$C$15,0,$F$15*$D$15*(1+$C$27)*(1+$C$28)^1) -> 0 | Y40: =IF(23<$C$15,0,$F$15*$D$15*(1+$C$27)*(1+$C$28)^1) -> 0 | Z40: =IF(24<$C$15,0,$F$15*$D$15*(1+$C$27)*(1+$C$28)^1) -> 0 | AA40: =IF(25<$C$15,0,$G$15*$D$15*(1+$C$27)*(1+$C$28)^2) -> 2020.788 | AB40: =IF(26<$C$15,0,$G$15*$D$15*(1+$C$27)*(1+$C$28)^2) -> 2020.788 | AC40: =IF(27<$C$15,0,$G$15*$D$15*(1+$C$27)*(1+$C$28)^2) -> 2020.788 | AD40: =IF(28<$C$15,0,$G$15*$D$15*(1+$C$27)*(1+$C$28)^2) -> 2020.788 | AE40: =IF(29<$C$15,0,$G$15*$D$15*(1+$C$27)*(1+$C$28)^2) -> 2020.788 | AF40: =IF(30<$C$15,0,$G$15*$D$15*(1+$C$27)*(1+$C$28)^2) -> 2020.788 | AG40: =IF(31<$C$15,0,$G$15*$D$15*(1+$C$27)*(1+$C$28)^2) -> 2020.788 | AH40: =IF(32<$C$15,0,$G$15*$D$15*(1+$C$27)*(1+$C$28)^2) -> 2020.788 | AI40: =IF(33<$C$15,0,$G$15*$D$15*(1+$C$27)*(1+$C$28)^2) -> 2020.788 | AJ40: =IF(34<$C$15,0,$G$15*$D$15*(1+$C$27)*(1+$C$28)^2) -> 2020.788 | AK40: =IF(35<$C$15,0,$G$15*$D$15*(1+$C$27)*(1+$C$28)^2) -> 2020.788 | AL40: =IF(36<$C$15,0,$G$15*$D$15*(1+$C$27)*(1+$C$28)^2) -> 2020.788 | AN40: =SUM(C40:N40) -> 0 | AO40: =SUM(O40:Z40) -> 0 | AP40: =SUM(AA40:AL40) -> 24249.456
A41: Bilingual curriculum producer | B41: Curriculum and Delivery | C41: =IF(1<$C$16,0,$E$16*$D$16*(1+$C$27)*(1+$C$28)^0) -> 0 | D41: =IF(2<$C$16,0,$E$16*$D$16*(1+$C$27)*(1+$C$28)^0) -> 0 | E41: =IF(3<$C$16,0,$E$16*$D$16*(1+$C$27)*(1+$C$28)^0) -> 0 | F41: =IF(4<$C$16,0,$E$16*$D$16*(1+$C$27)*(1+$C$28)^0) -> 0 | G41: =IF(5<$C$16,0,$E$16*$D$16*(1+$C$27)*(1+$C$28)^0) -> 0 | H41: =IF(6<$C$16,0,$E$16*$D$16*(1+$C$27)*(1+$C$28)^0) -> 0 | I41: =IF(7<$C$16,0,$E$16*$D$16*(1+$C$27)*(1+$C$28)^0) -> 0 | J41: =IF(8<$C$16,0,$E$16*$D$16*(1+$C$27)*(1+$C$28)^0) -> 0 | K41: =IF(9<$C$16,0,$E$16*$D$16*(1+$C$27)*(1+$C$28)^0) -> 0 | L41: =IF(10<$C$16,0,$E$16*$D$16*(1+$C$27)*(1+$C$28)^0) -> 0 | M41: =IF(11<$C$16,0,$E$16*$D$16*(1+$C$27)*(1+$C$28)^0) -> 0 | N41: =IF(12<$C$16,0,$E$16*$D$16*(1+$C$27)*(1+$C$28)^0) -> 0 | O41: =IF(13<$C$16,0,$F$16*$D$16*(1+$C$27)*(1+$C$28)^1) -> 0 | P41: =IF(14<$C$16,0,$F$16*$D$16*(1+$C$27)*(1+$C$28)^1) -> 0 | Q41: =IF(15<$C$16,0,$F$16*$D$16*(1+$C$27)*(1+$C$28)^1) -> 0 | R41: =IF(16<$C$16,0,$F$16*$D$16*(1+$C$27)*(1+$C$28)^1) -> 0 | S41: =IF(17<$C$16,0,$F$16*$D$16*(1+$C$27)*(1+$C$28)^1) -> 0 | T41: =IF(18<$C$16,0,$F$16*$D$16*(1+$C$27)*(1+$C$28)^1) -> 0 | U41: =IF(19<$C$16,0,$F$16*$D$16*(1+$C$27)*(1+$C$28)^1) -> 0 | V41: =IF(20<$C$16,0,$F$16*$D$16*(1+$C$27)*(1+$C$28)^1) -> 0 | W41: =IF(21<$C$16,0,$F$16*$D$16*(1+$C$27)*(1+$C$28)^1) -> 0 | X41: =IF(22<$C$16,0,$F$16*$D$16*(1+$C$27)*(1+$C$28)^1) -> 0 | Y41: =IF(23<$C$16,0,$F$16*$D$16*(1+$C$27)*(1+$C$28)^1) -> 0 | Z41: =IF(24<$C$16,0,$F$16*$D$16*(1+$C$27)*(1+$C$28)^1) -> 0 | AA41: =IF(25<$C$16,0,$G$16*$D$16*(1+$C$27)*(1+$C$28)^2) -> 0 | AB41: =IF(26<$C$16,0,$G$16*$D$16*(1+$C$27)*(1+$C$28)^2) -> 0 | AC41: =IF(27<$C$16,0,$G$16*$D$16*(1+$C$27)*(1+$C$28)^2) -> 0 | AD41: =IF(28<$C$16,0,$G$16*$D$16*(1+$C$27)*(1+$C$28)^2) -> 0 | AE41: =IF(29<$C$16,0,$G$16*$D$16*(1+$C$27)*(1+$C$28)^2) -> 0 | AF41: =IF(30<$C$16,0,$G$16*$D$16*(1+$C$27)*(1+$C$28)^2) -> 0 | AG41: =IF(31<$C$16,0,$G$16*$D$16*(1+$C$27)*(1+$C$28)^2) -> 0 | AH41: =IF(32<$C$16,0,$G$16*$D$16*(1+$C$27)*(1+$C$28)^2) -> 0 | AI41: =IF(33<$C$16,0,$G$16*$D$16*(1+$C$27)*(1+$C$28)^2) -> 0 | AJ41: =IF(34<$C$16,0,$G$16*$D$16*(1+$C$27)*(1+$C$28)^2) -> 0 | AK41: =IF(35<$C$16,0,$G$16*$D$16*(1+$C$27)*(1+$C$28)^2) -> 0 | AL41: =IF(36<$C$16,0,$G$16*$D$16*(1+$C$27)*(1+$C$28)^2) -> 0 | AN41: =SUM(C41:N41) -> 0 | AO41: =SUM(O41:Z41) -> 0 | AP41: =SUM(AA41:AL41) -> 0
A42: Head of Partnerships — Egypt | B42: Institutional Partnerships | C42: =IF(1<$C$17,0,$E$17*$D$17*(1+$C$27)*(1+$C$28)^0) -> 2541 | D42: =IF(2<$C$17,0,$E$17*$D$17*(1+$C$27)*(1+$C$28)^0) -> 2541 | E42: =IF(3<$C$17,0,$E$17*$D$17*(1+$C$27)*(1+$C$28)^0) -> 2541 | F42: =IF(4<$C$17,0,$E$17*$D$17*(1+$C$27)*(1+$C$28)^0) -> 2541 | G42: =IF(5<$C$17,0,$E$17*$D$17*(1+$C$27)*(1+$C$28)^0) -> 2541 | H42: =IF(6<$C$17,0,$E$17*$D$17*(1+$C$27)*(1+$C$28)^0) -> 2541 | I42: =IF(7<$C$17,0,$E$17*$D$17*(1+$C$27)*(1+$C$28)^0) -> 2541 | J42: =IF(8<$C$17,0,$E$17*$D$17*(1+$C$27)*(1+$C$28)^0) -> 2541 | K42: =IF(9<$C$17,0,$E$17*$D$17*(1+$C$27)*(1+$C$28)^0) -> 2541 | L42: =IF(10<$C$17,0,$E$17*$D$17*(1+$C$27)*(1+$C$28)^0) -> 2541 | M42: =IF(11<$C$17,0,$E$17*$D$17*(1+$C$27)*(1+$C$28)^0) -> 2541 | N42: =IF(12<$C$17,0,$E$17*$D$17*(1+$C$27)*(1+$C$28)^0) -> 2541 | O42: =IF(13<$C$17,0,$F$17*$D$17*(1+$C$27)*(1+$C$28)^1) -> 2744.28 | P42: =IF(14<$C$17,0,$F$17*$D$17*(1+$C$27)*(1+$C$28)^1) -> 2744.28 | Q42: =IF(15<$C$17,0,$F$17*$D$17*(1+$C$27)*(1+$C$28)^1) -> 2744.28 | R42: =IF(16<$C$17,0,$F$17*$D$17*(1+$C$27)*(1+$C$28)^1) -> 2744.28 | S42: =IF(17<$C$17,0,$F$17*$D$17*(1+$C$27)*(1+$C$28)^1) -> 2744.28 | T42: =IF(18<$C$17,0,$F$17*$D$17*(1+$C$27)*(1+$C$28)^1) -> 2744.28 | U42: =IF(19<$C$17,0,$F$17*$D$17*(1+$C$27)*(1+$C$28)^1) -> 2744.28 | V42: =IF(20<$C$17,0,$F$17*$D$17*(1+$C$27)*(1+$C$28)^1) -> 2744.28 | W42: =IF(21<$C$17,0,$F$17*$D$17*(1+$C$27)*(1+$C$28)^1) -> 2744.28 | X42: =IF(22<$C$17,0,$F$17*$D$17*(1+$C$27)*(1+$C$28)^1) -> 2744.28 | Y42: =IF(23<$C$17,0,$F$17*$D$17*(1+$C$27)*(1+$C$28)^1) -> 2744.28 | Z42: =IF(24<$C$17,0,$F$17*$D$17*(1+$C$27)*(1+$C$28)^1) -> 2744.28 | AA42: =IF(25<$C$17,0,$G$17*$D$17*(1+$C$27)*(1+$C$28)^2) -> 2963.8224 | AB42: =IF(26<$C$17,0,$G$17*$D$17*(1+$C$27)*(1+$C$28)^2) -> 2963.8224 | AC42: =IF(27<$C$17,0,$G$17*$D$17*(1+$C$27)*(1+$C$28)^2) -> 2963.8224 | AD42: =IF(28<$C$17,0,$G$17*$D$17*(1+$C$27)*(1+$C$28)^2) -> 2963.8224 | AE42: =IF(29<$C$17,0,$G$17*$D$17*(1+$C$27)*(1+$C$28)^2) -> 2963.8224 | AF42: =IF(30<$C$17,0,$G$17*$D$17*(1+$C$27)*(1+$C$28)^2) -> 2963.8224 | AG42: =IF(31<$C$17,0,$G$17*$D$17*(1+$C$27)*(1+$C$28)^2) -> 2963.8224 | AH42: =IF(32<$C$17,0,$G$17*$D$17*(1+$C$27)*(1+$C$28)^2) -> 2963.8224 | AI42: =IF(33<$C$17,0,$G$17*$D$17*(1+$C$27)*(1+$C$28)^2) -> 2963.8224 | AJ42: =IF(34<$C$17,0,$G$17*$D$17*(1+$C$27)*(1+$C$28)^2) -> 2963.8224 | AK42: =IF(35<$C$17,0,$G$17*$D$17*(1+$C$27)*(1+$C$28)^2) -> 2963.8224 | AL42: =IF(36<$C$17,0,$G$17*$D$17*(1+$C$27)*(1+$C$28)^2) -> 2963.8224 | AN42: =SUM(C42:N42) -> 30492 | AO42: =SUM(O42:Z42) -> 32931.36 | AP42: =SUM(AA42:AL42) -> 35565.869
A43: Country Manager — KSA (Riyadh) | B43: Institutional Partnerships | C43: =IF(1<$C$18,0,$E$18*$D$18*(1+$C$27)*(1+$C$28)^0) -> 0 | D43: =IF(2<$C$18,0,$E$18*$D$18*(1+$C$27)*(1+$C$28)^0) -> 0 | E43: =IF(3<$C$18,0,$E$18*$D$18*(1+$C$27)*(1+$C$28)^0) -> 0 | F43: =IF(4<$C$18,0,$E$18*$D$18*(1+$C$27)*(1+$C$28)^0) -> 0 | G43: =IF(5<$C$18,0,$E$18*$D$18*(1+$C$27)*(1+$C$28)^0) -> 0 | H43: =IF(6<$C$18,0,$E$18*$D$18*(1+$C$27)*(1+$C$28)^0) -> 0 | I43: =IF(7<$C$18,0,$E$18*$D$18*(1+$C$27)*(1+$C$28)^0) -> 0 | J43: =IF(8<$C$18,0,$E$18*$D$18*(1+$C$27)*(1+$C$28)^0) -> 0 | K43: =IF(9<$C$18,0,$E$18*$D$18*(1+$C$27)*(1+$C$28)^0) -> 0 | L43: =IF(10<$C$18,0,$E$18*$D$18*(1+$C$27)*(1+$C$28)^0) -> 0 | M43: =IF(11<$C$18,0,$E$18*$D$18*(1+$C$27)*(1+$C$28)^0) -> 0 | N43: =IF(12<$C$18,0,$E$18*$D$18*(1+$C$27)*(1+$C$28)^0) -> 0 | O43: =IF(13<$C$18,0,$F$18*$D$18*(1+$C$27)*(1+$C$28)^1) -> 6237 | P43: =IF(14<$C$18,0,$F$18*$D$18*(1+$C$27)*(1+$C$28)^1) -> 6237 | Q43: =IF(15<$C$18,0,$F$18*$D$18*(1+$C$27)*(1+$C$28)^1) -> 6237 | R43: =IF(16<$C$18,0,$F$18*$D$18*(1+$C$27)*(1+$C$28)^1) -> 6237 | S43: =IF(17<$C$18,0,$F$18*$D$18*(1+$C$27)*(1+$C$28)^1) -> 6237 | T43: =IF(18<$C$18,0,$F$18*$D$18*(1+$C$27)*(1+$C$28)^1) -> 6237 | U43: =IF(19<$C$18,0,$F$18*$D$18*(1+$C$27)*(1+$C$28)^1) -> 6237 | V43: =IF(20<$C$18,0,$F$18*$D$18*(1+$C$27)*(1+$C$28)^1) -> 6237 | W43: =IF(21<$C$18,0,$F$18*$D$18*(1+$C$27)*(1+$C$28)^1) -> 6237 | X43: =IF(22<$C$18,0,$F$18*$D$18*(1+$C$27)*(1+$C$28)^1) -> 6237 | Y43: =IF(23<$C$18,0,$F$18*$D$18*(1+$C$27)*(1+$C$28)^1) -> 6237 | Z43: =IF(24<$C$18,0,$F$18*$D$18*(1+$C$27)*(1+$C$28)^1) -> 6237 | AA43: =IF(25<$C$18,0,$G$18*$D$18*(1+$C$27)*(1+$C$28)^2) -> 6735.96 | AB43: =IF(26<$C$18,0,$G$18*$D$18*(1+$C$27)*(1+$C$28)^2) -> 6735.96 | AC43: =IF(27<$C$18,0,$G$18*$D$18*(1+$C$27)*(1+$C$28)^2) -> 6735.96 | AD43: =IF(28<$C$18,0,$G$18*$D$18*(1+$C$27)*(1+$C$28)^2) -> 6735.96 | AE43: =IF(29<$C$18,0,$G$18*$D$18*(1+$C$27)*(1+$C$28)^2) -> 6735.96 | AF43: =IF(30<$C$18,0,$G$18*$D$18*(1+$C$27)*(1+$C$28)^2) -> 6735.96 | AG43: =IF(31<$C$18,0,$G$18*$D$18*(1+$C$27)*(1+$C$28)^2) -> 6735.96 | AH43: =IF(32<$C$18,0,$G$18*$D$18*(1+$C$27)*(1+$C$28)^2) -> 6735.96 | AI43: =IF(33<$C$18,0,$G$18*$D$18*(1+$C$27)*(1+$C$28)^2) -> 6735.96 | AJ43: =IF(34<$C$18,0,$G$18*$D$18*(1+$C$27)*(1+$C$28)^2) -> 6735.96 | AK43: =IF(35<$C$18,0,$G$18*$D$18*(1+$C$27)*(1+$C$28)^2) -> 6735.96 | AL43: =IF(36<$C$18,0,$G$18*$D$18*(1+$C$27)*(1+$C$28)^2) -> 6735.96 | AN43: =SUM(C43:N43) -> 0 | AO43: =SUM(O43:Z43) -> 74844 | AP43: =SUM(AA43:AL43) -> 80831.52
A44: Head of Government, Initiatives and Donors | B44: Institutional Partnerships | C44: =IF(1<$C$19,0,$E$19*$D$19*(1+$C$27)*(1+$C$28)^0) -> 0 | D44: =IF(2<$C$19,0,$E$19*$D$19*(1+$C$27)*(1+$C$28)^0) -> 0 | E44: =IF(3<$C$19,0,$E$19*$D$19*(1+$C$27)*(1+$C$28)^0) -> 0 | F44: =IF(4<$C$19,0,$E$19*$D$19*(1+$C$27)*(1+$C$28)^0) -> 0 | G44: =IF(5<$C$19,0,$E$19*$D$19*(1+$C$27)*(1+$C$28)^0) -> 0 | H44: =IF(6<$C$19,0,$E$19*$D$19*(1+$C$27)*(1+$C$28)^0) -> 0 | I44: =IF(7<$C$19,0,$E$19*$D$19*(1+$C$27)*(1+$C$28)^0) -> 0 | J44: =IF(8<$C$19,0,$E$19*$D$19*(1+$C$27)*(1+$C$28)^0) -> 0 | K44: =IF(9<$C$19,0,$E$19*$D$19*(1+$C$27)*(1+$C$28)^0) -> 0 | L44: =IF(10<$C$19,0,$E$19*$D$19*(1+$C$27)*(1+$C$28)^0) -> 0 | M44: =IF(11<$C$19,0,$E$19*$D$19*(1+$C$27)*(1+$C$28)^0) -> 0 | N44: =IF(12<$C$19,0,$E$19*$D$19*(1+$C$27)*(1+$C$28)^0) -> 0 | O44: =IF(13<$C$19,0,$F$19*$D$19*(1+$C$27)*(1+$C$28)^1) -> 0 | P44: =IF(14<$C$19,0,$F$19*$D$19*(1+$C$27)*(1+$C$28)^1) -> 0 | Q44: =IF(15<$C$19,0,$F$19*$D$19*(1+$C$27)*(1+$C$28)^1) -> 0 | R44: =IF(16<$C$19,0,$F$19*$D$19*(1+$C$27)*(1+$C$28)^1) -> 0 | S44: =IF(17<$C$19,0,$F$19*$D$19*(1+$C$27)*(1+$C$28)^1) -> 0 | T44: =IF(18<$C$19,0,$F$19*$D$19*(1+$C$27)*(1+$C$28)^1) -> 0 | U44: =IF(19<$C$19,0,$F$19*$D$19*(1+$C$27)*(1+$C$28)^1) -> 0 | V44: =IF(20<$C$19,0,$F$19*$D$19*(1+$C$27)*(1+$C$28)^1) -> 0 | W44: =IF(21<$C$19,0,$F$19*$D$19*(1+$C$27)*(1+$C$28)^1) -> 0 | X44: =IF(22<$C$19,0,$F$19*$D$19*(1+$C$27)*(1+$C$28)^1) -> 0 | Y44: =IF(23<$C$19,0,$F$19*$D$19*(1+$C$27)*(1+$C$28)^1) -> 0 | Z44: =IF(24<$C$19,0,$F$19*$D$19*(1+$C$27)*(1+$C$28)^1) -> 0 | AA44: =IF(25<$C$19,0,$G$19*$D$19*(1+$C$27)*(1+$C$28)^2) -> 3502.6992 | AB44: =IF(26<$C$19,0,$G$19*$D$19*(1+$C$27)*(1+$C$28)^2) -> 3502.6992 | AC44: =IF(27<$C$19,0,$G$19*$D$19*(1+$C$27)*(1+$C$28)^2) -> 3502.6992 | AD44: =IF(28<$C$19,0,$G$19*$D$19*(1+$C$27)*(1+$C$28)^2) -> 3502.6992 | AE44: =IF(29<$C$19,0,$G$19*$D$19*(1+$C$27)*(1+$C$28)^2) -> 3502.6992 | AF44: =IF(30<$C$19,0,$G$19*$D$19*(1+$C$27)*(1+$C$28)^2) -> 3502.6992 | AG44: =IF(31<$C$19,0,$G$19*$D$19*(1+$C$27)*(1+$C$28)^2) -> 3502.6992 | AH44: =IF(32<$C$19,0,$G$19*$D$19*(1+$C$27)*(1+$C$28)^2) -> 3502.6992 | AI44: =IF(33<$C$19,0,$G$19*$D$19*(1+$C$27)*(1+$C$28)^2) -> 3502.6992 | AJ44: =IF(34<$C$19,0,$G$19*$D$19*(1+$C$27)*(1+$C$28)^2) -> 3502.6992 | AK44: =IF(35<$C$19,0,$G$19*$D$19*(1+$C$27)*(1+$C$28)^2) -> 3502.6992 | AL44: =IF(36<$C$19,0,$G$19*$D$19*(1+$C$27)*(1+$C$28)^2) -> 3502.6992 | AN44: =SUM(C44:N44) -> 0 | AO44: =SUM(O44:Z44) -> 0 | AP44: =SUM(AA44:AL44) -> 42032.39
A45: Partnerships and bids associate | B45: Institutional Partnerships | C45: =IF(1<$C$20,0,$E$20*$D$20*(1+$C$27)*(1+$C$28)^0) -> 0 | D45: =IF(2<$C$20,0,$E$20*$D$20*(1+$C$27)*(1+$C$28)^0) -> 0 | E45: =IF(3<$C$20,0,$E$20*$D$20*(1+$C$27)*(1+$C$28)^0) -> 0 | F45: =IF(4<$C$20,0,$E$20*$D$20*(1+$C$27)*(1+$C$28)^0) -> 0 | G45: =IF(5<$C$20,0,$E$20*$D$20*(1+$C$27)*(1+$C$28)^0) -> 0 | H45: =IF(6<$C$20,0,$E$20*$D$20*(1+$C$27)*(1+$C$28)^0) -> 0 | I45: =IF(7<$C$20,0,$E$20*$D$20*(1+$C$27)*(1+$C$28)^0) -> 0 | J45: =IF(8<$C$20,0,$E$20*$D$20*(1+$C$27)*(1+$C$28)^0) -> 0 | K45: =IF(9<$C$20,0,$E$20*$D$20*(1+$C$27)*(1+$C$28)^0) -> 0 | L45: =IF(10<$C$20,0,$E$20*$D$20*(1+$C$27)*(1+$C$28)^0) -> 0 | M45: =IF(11<$C$20,0,$E$20*$D$20*(1+$C$27)*(1+$C$28)^0) -> 0 | N45: =IF(12<$C$20,0,$E$20*$D$20*(1+$C$27)*(1+$C$28)^0) -> 0 | O45: =IF(13<$C$20,0,$F$20*$D$20*(1+$C$27)*(1+$C$28)^1) -> 0 | P45: =IF(14<$C$20,0,$F$20*$D$20*(1+$C$27)*(1+$C$28)^1) -> 0 | Q45: =IF(15<$C$20,0,$F$20*$D$20*(1+$C$27)*(1+$C$28)^1) -> 0 | R45: =IF(16<$C$20,0,$F$20*$D$20*(1+$C$27)*(1+$C$28)^1) -> 0 | S45: =IF(17<$C$20,0,$F$20*$D$20*(1+$C$27)*(1+$C$28)^1) -> 0 | T45: =IF(18<$C$20,0,$F$20*$D$20*(1+$C$27)*(1+$C$28)^1) -> 0 | U45: =IF(19<$C$20,0,$F$20*$D$20*(1+$C$27)*(1+$C$28)^1) -> 0 | V45: =IF(20<$C$20,0,$F$20*$D$20*(1+$C$27)*(1+$C$28)^1) -> 0 | W45: =IF(21<$C$20,0,$F$20*$D$20*(1+$C$27)*(1+$C$28)^1) -> 0 | X45: =IF(22<$C$20,0,$F$20*$D$20*(1+$C$27)*(1+$C$28)^1) -> 0 | Y45: =IF(23<$C$20,0,$F$20*$D$20*(1+$C$27)*(1+$C$28)^1) -> 0 | Z45: =IF(24<$C$20,0,$F$20*$D$20*(1+$C$27)*(1+$C$28)^1) -> 0 | AA45: =IF(25<$C$20,0,$G$20*$D$20*(1+$C$27)*(1+$C$28)^2) -> 1616.6304 | AB45: =IF(26<$C$20,0,$G$20*$D$20*(1+$C$27)*(1+$C$28)^2) -> 1616.6304 | AC45: =IF(27<$C$20,0,$G$20*$D$20*(1+$C$27)*(1+$C$28)^2) -> 1616.6304 | AD45: =IF(28<$C$20,0,$G$20*$D$20*(1+$C$27)*(1+$C$28)^2) -> 1616.6304 | AE45: =IF(29<$C$20,0,$G$20*$D$20*(1+$C$27)*(1+$C$28)^2) -> 1616.6304 | AF45: =IF(30<$C$20,0,$G$20*$D$20*(1+$C$27)*(1+$C$28)^2) -> 1616.6304 | AG45: =IF(31<$C$20,0,$G$20*$D$20*(1+$C$27)*(1+$C$28)^2) -> 1616.6304 | AH45: =IF(32<$C$20,0,$G$20*$D$20*(1+$C$27)*(1+$C$28)^2) -> 1616.6304 | AI45: =IF(33<$C$20,0,$G$20*$D$20*(1+$C$27)*(1+$C$28)^2) -> 1616.6304 | AJ45: =IF(34<$C$20,0,$G$20*$D$20*(1+$C$27)*(1+$C$28)^2) -> 1616.6304 | AK45: =IF(35<$C$20,0,$G$20*$D$20*(1+$C$27)*(1+$C$28)^2) -> 1616.6304 | AL45: =IF(36<$C$20,0,$G$20*$D$20*(1+$C$27)*(1+$C$28)^2) -> 1616.6304 | AN45: =SUM(C45:N45) -> 0 | AO45: =SUM(O45:Z45) -> 0 | AP45: =SUM(AA45:AL45) -> 19399.565
A46: Head of Schools and Technical Education | B46: Institutional Partnerships | C46: =IF(1<$C$21,0,$E$21*$D$21*(1+$C$27)*(1+$C$28)^0) -> 0 | D46: =IF(2<$C$21,0,$E$21*$D$21*(1+$C$27)*(1+$C$28)^0) -> 0 | E46: =IF(3<$C$21,0,$E$21*$D$21*(1+$C$27)*(1+$C$28)^0) -> 0 | F46: =IF(4<$C$21,0,$E$21*$D$21*(1+$C$27)*(1+$C$28)^0) -> 0 | G46: =IF(5<$C$21,0,$E$21*$D$21*(1+$C$27)*(1+$C$28)^0) -> 0 | H46: =IF(6<$C$21,0,$E$21*$D$21*(1+$C$27)*(1+$C$28)^0) -> 0 | I46: =IF(7<$C$21,0,$E$21*$D$21*(1+$C$27)*(1+$C$28)^0) -> 0 | J46: =IF(8<$C$21,0,$E$21*$D$21*(1+$C$27)*(1+$C$28)^0) -> 0 | K46: =IF(9<$C$21,0,$E$21*$D$21*(1+$C$27)*(1+$C$28)^0) -> 0 | L46: =IF(10<$C$21,0,$E$21*$D$21*(1+$C$27)*(1+$C$28)^0) -> 0 | M46: =IF(11<$C$21,0,$E$21*$D$21*(1+$C$27)*(1+$C$28)^0) -> 0 | N46: =IF(12<$C$21,0,$E$21*$D$21*(1+$C$27)*(1+$C$28)^0) -> 0 | O46: =IF(13<$C$21,0,$F$21*$D$21*(1+$C$27)*(1+$C$28)^1) -> 0 | P46: =IF(14<$C$21,0,$F$21*$D$21*(1+$C$27)*(1+$C$28)^1) -> 0 | Q46: =IF(15<$C$21,0,$F$21*$D$21*(1+$C$27)*(1+$C$28)^1) -> 0 | R46: =IF(16<$C$21,0,$F$21*$D$21*(1+$C$27)*(1+$C$28)^1) -> 0 | S46: =IF(17<$C$21,0,$F$21*$D$21*(1+$C$27)*(1+$C$28)^1) -> 0 | T46: =IF(18<$C$21,0,$F$21*$D$21*(1+$C$27)*(1+$C$28)^1) -> 0 | U46: =IF(19<$C$21,0,$F$21*$D$21*(1+$C$27)*(1+$C$28)^1) -> 0 | V46: =IF(20<$C$21,0,$F$21*$D$21*(1+$C$27)*(1+$C$28)^1) -> 0 | W46: =IF(21<$C$21,0,$F$21*$D$21*(1+$C$27)*(1+$C$28)^1) -> 0 | X46: =IF(22<$C$21,0,$F$21*$D$21*(1+$C$27)*(1+$C$28)^1) -> 0 | Y46: =IF(23<$C$21,0,$F$21*$D$21*(1+$C$27)*(1+$C$28)^1) -> 0 | Z46: =IF(24<$C$21,0,$F$21*$D$21*(1+$C$27)*(1+$C$28)^1) -> 0 | AA46: =IF(25<$C$21,0,$G$21*$D$21*(1+$C$27)*(1+$C$28)^2) -> 0 | AB46: =IF(26<$C$21,0,$G$21*$D$21*(1+$C$27)*(1+$C$28)^2) -> 0 | AC46: =IF(27<$C$21,0,$G$21*$D$21*(1+$C$27)*(1+$C$28)^2) -> 0 | AD46: =IF(28<$C$21,0,$G$21*$D$21*(1+$C$27)*(1+$C$28)^2) -> 0 | AE46: =IF(29<$C$21,0,$G$21*$D$21*(1+$C$27)*(1+$C$28)^2) -> 0 | AF46: =IF(30<$C$21,0,$G$21*$D$21*(1+$C$27)*(1+$C$28)^2) -> 0 | AG46: =IF(31<$C$21,0,$G$21*$D$21*(1+$C$27)*(1+$C$28)^2) -> 0 | AH46: =IF(32<$C$21,0,$G$21*$D$21*(1+$C$27)*(1+$C$28)^2) -> 0 | AI46: =IF(33<$C$21,0,$G$21*$D$21*(1+$C$27)*(1+$C$28)^2) -> 0 | AJ46: =IF(34<$C$21,0,$G$21*$D$21*(1+$C$27)*(1+$C$28)^2) -> 0 | AK46: =IF(35<$C$21,0,$G$21*$D$21*(1+$C$27)*(1+$C$28)^2) -> 0 | AL46: =IF(36<$C$21,0,$G$21*$D$21*(1+$C$27)*(1+$C$28)^2) -> 0 | AN46: =SUM(C46:N46) -> 0 | AO46: =SUM(O46:Z46) -> 0 | AP46: =SUM(AA46:AL46) -> 0
A47: Account manager — renewals | B47: Institutional Partnerships | C47: =IF(1<$C$22,0,$E$22*$D$22*(1+$C$27)*(1+$C$28)^0) -> 0 | D47: =IF(2<$C$22,0,$E$22*$D$22*(1+$C$27)*(1+$C$28)^0) -> 0 | E47: =IF(3<$C$22,0,$E$22*$D$22*(1+$C$27)*(1+$C$28)^0) -> 0 | F47: =IF(4<$C$22,0,$E$22*$D$22*(1+$C$27)*(1+$C$28)^0) -> 0 | G47: =IF(5<$C$22,0,$E$22*$D$22*(1+$C$27)*(1+$C$28)^0) -> 0 | H47: =IF(6<$C$22,0,$E$22*$D$22*(1+$C$27)*(1+$C$28)^0) -> 0 | I47: =IF(7<$C$22,0,$E$22*$D$22*(1+$C$27)*(1+$C$28)^0) -> 0 | J47: =IF(8<$C$22,0,$E$22*$D$22*(1+$C$27)*(1+$C$28)^0) -> 0 | K47: =IF(9<$C$22,0,$E$22*$D$22*(1+$C$27)*(1+$C$28)^0) -> 0 | L47: =IF(10<$C$22,0,$E$22*$D$22*(1+$C$27)*(1+$C$28)^0) -> 0 | M47: =IF(11<$C$22,0,$E$22*$D$22*(1+$C$27)*(1+$C$28)^0) -> 0 | N47: =IF(12<$C$22,0,$E$22*$D$22*(1+$C$27)*(1+$C$28)^0) -> 0 | O47: =IF(13<$C$22,0,$F$22*$D$22*(1+$C$27)*(1+$C$28)^1) -> 0 | P47: =IF(14<$C$22,0,$F$22*$D$22*(1+$C$27)*(1+$C$28)^1) -> 0 | Q47: =IF(15<$C$22,0,$F$22*$D$22*(1+$C$27)*(1+$C$28)^1) -> 0 | R47: =IF(16<$C$22,0,$F$22*$D$22*(1+$C$27)*(1+$C$28)^1) -> 0 | S47: =IF(17<$C$22,0,$F$22*$D$22*(1+$C$27)*(1+$C$28)^1) -> 0 | T47: =IF(18<$C$22,0,$F$22*$D$22*(1+$C$27)*(1+$C$28)^1) -> 0 | U47: =IF(19<$C$22,0,$F$22*$D$22*(1+$C$27)*(1+$C$28)^1) -> 0 | V47: =IF(20<$C$22,0,$F$22*$D$22*(1+$C$27)*(1+$C$28)^1) -> 0 | W47: =IF(21<$C$22,0,$F$22*$D$22*(1+$C$27)*(1+$C$28)^1) -> 0 | X47: =IF(22<$C$22,0,$F$22*$D$22*(1+$C$27)*(1+$C$28)^1) -> 0 | Y47: =IF(23<$C$22,0,$F$22*$D$22*(1+$C$27)*(1+$C$28)^1) -> 0 | Z47: =IF(24<$C$22,0,$F$22*$D$22*(1+$C$27)*(1+$C$28)^1) -> 0 | AA47: =IF(25<$C$22,0,$G$22*$D$22*(1+$C$27)*(1+$C$28)^2) -> 0 | AB47: =IF(26<$C$22,0,$G$22*$D$22*(1+$C$27)*(1+$C$28)^2) -> 0 | AC47: =IF(27<$C$22,0,$G$22*$D$22*(1+$C$27)*(1+$C$28)^2) -> 0 | AD47: =IF(28<$C$22,0,$G$22*$D$22*(1+$C$27)*(1+$C$28)^2) -> 0 | AE47: =IF(29<$C$22,0,$G$22*$D$22*(1+$C$27)*(1+$C$28)^2) -> 0 | AF47: =IF(30<$C$22,0,$G$22*$D$22*(1+$C$27)*(1+$C$28)^2) -> 0 | AG47: =IF(31<$C$22,0,$G$22*$D$22*(1+$C$27)*(1+$C$28)^2) -> 0 | AH47: =IF(32<$C$22,0,$G$22*$D$22*(1+$C$27)*(1+$C$28)^2) -> 0 | AI47: =IF(33<$C$22,0,$G$22*$D$22*(1+$C$27)*(1+$C$28)^2) -> 0 | AJ47: =IF(34<$C$22,0,$G$22*$D$22*(1+$C$27)*(1+$C$28)^2) -> 0 | AK47: =IF(35<$C$22,0,$G$22*$D$22*(1+$C$27)*(1+$C$28)^2) -> 0 | AL47: =IF(36<$C$22,0,$G$22*$D$22*(1+$C$27)*(1+$C$28)^2) -> 0 | AN47: =SUM(C47:N47) -> 0 | AO47: =SUM(O47:Z47) -> 0 | AP47: =SUM(AA47:AL47) -> 0
A48: Head of Growth and Content | B48: Growth and Content | C48: =IF(1<$C$23,0,$E$23*$D$23*(1+$C$27)*(1+$C$28)^0) -> 2310 | D48: =IF(2<$C$23,0,$E$23*$D$23*(1+$C$27)*(1+$C$28)^0) -> 2310 | E48: =IF(3<$C$23,0,$E$23*$D$23*(1+$C$27)*(1+$C$28)^0) -> 2310 | F48: =IF(4<$C$23,0,$E$23*$D$23*(1+$C$27)*(1+$C$28)^0) -> 2310 | G48: =IF(5<$C$23,0,$E$23*$D$23*(1+$C$27)*(1+$C$28)^0) -> 2310 | H48: =IF(6<$C$23,0,$E$23*$D$23*(1+$C$27)*(1+$C$28)^0) -> 2310 | I48: =IF(7<$C$23,0,$E$23*$D$23*(1+$C$27)*(1+$C$28)^0) -> 2310 | J48: =IF(8<$C$23,0,$E$23*$D$23*(1+$C$27)*(1+$C$28)^0) -> 2310 | K48: =IF(9<$C$23,0,$E$23*$D$23*(1+$C$27)*(1+$C$28)^0) -> 2310 | L48: =IF(10<$C$23,0,$E$23*$D$23*(1+$C$27)*(1+$C$28)^0) -> 2310 | M48: =IF(11<$C$23,0,$E$23*$D$23*(1+$C$27)*(1+$C$28)^0) -> 2310 | N48: =IF(12<$C$23,0,$E$23*$D$23*(1+$C$27)*(1+$C$28)^0) -> 2310 | O48: =IF(13<$C$23,0,$F$23*$D$23*(1+$C$27)*(1+$C$28)^1) -> 2494.8 | P48: =IF(14<$C$23,0,$F$23*$D$23*(1+$C$27)*(1+$C$28)^1) -> 2494.8 | Q48: =IF(15<$C$23,0,$F$23*$D$23*(1+$C$27)*(1+$C$28)^1) -> 2494.8 | R48: =IF(16<$C$23,0,$F$23*$D$23*(1+$C$27)*(1+$C$28)^1) -> 2494.8 | S48: =IF(17<$C$23,0,$F$23*$D$23*(1+$C$27)*(1+$C$28)^1) -> 2494.8 | T48: =IF(18<$C$23,0,$F$23*$D$23*(1+$C$27)*(1+$C$28)^1) -> 2494.8 | U48: =IF(19<$C$23,0,$F$23*$D$23*(1+$C$27)*(1+$C$28)^1) -> 2494.8 | V48: =IF(20<$C$23,0,$F$23*$D$23*(1+$C$27)*(1+$C$28)^1) -> 2494.8 | W48: =IF(21<$C$23,0,$F$23*$D$23*(1+$C$27)*(1+$C$28)^1) -> 2494.8 | X48: =IF(22<$C$23,0,$F$23*$D$23*(1+$C$27)*(1+$C$28)^1) -> 2494.8 | Y48: =IF(23<$C$23,0,$F$23*$D$23*(1+$C$27)*(1+$C$28)^1) -> 2494.8 | Z48: =IF(24<$C$23,0,$F$23*$D$23*(1+$C$27)*(1+$C$28)^1) -> 2494.8 | AA48: =IF(25<$C$23,0,$G$23*$D$23*(1+$C$27)*(1+$C$28)^2) -> 2694.384 | AB48: =IF(26<$C$23,0,$G$23*$D$23*(1+$C$27)*(1+$C$28)^2) -> 2694.384 | AC48: =IF(27<$C$23,0,$G$23*$D$23*(1+$C$27)*(1+$C$28)^2) -> 2694.384 | AD48: =IF(28<$C$23,0,$G$23*$D$23*(1+$C$27)*(1+$C$28)^2) -> 2694.384 | AE48: =IF(29<$C$23,0,$G$23*$D$23*(1+$C$27)*(1+$C$28)^2) -> 2694.384 | AF48: =IF(30<$C$23,0,$G$23*$D$23*(1+$C$27)*(1+$C$28)^2) -> 2694.384 | AG48: =IF(31<$C$23,0,$G$23*$D$23*(1+$C$27)*(1+$C$28)^2) -> 2694.384 | AH48: =IF(32<$C$23,0,$G$23*$D$23*(1+$C$27)*(1+$C$28)^2) -> 2694.384 | AI48: =IF(33<$C$23,0,$G$23*$D$23*(1+$C$27)*(1+$C$28)^2) -> 2694.384 | AJ48: =IF(34<$C$23,0,$G$23*$D$23*(1+$C$27)*(1+$C$28)^2) -> 2694.384 | AK48: =IF(35<$C$23,0,$G$23*$D$23*(1+$C$27)*(1+$C$28)^2) -> 2694.384 | AL48: =IF(36<$C$23,0,$G$23*$D$23*(1+$C$27)*(1+$C$28)^2) -> 2694.384 | AN48: =SUM(C48:N48) -> 27720 | AO48: =SUM(O48:Z48) -> 29937.6 | AP48: =SUM(AA48:AL48) -> 32332.608
A49: Student success (bilingual) | B49: Growth and Content | C49: =IF(1<$C$24,0,$E$24*$D$24*(1+$C$27)*(1+$C$28)^0) -> 0 | D49: =IF(2<$C$24,0,$E$24*$D$24*(1+$C$27)*(1+$C$28)^0) -> 0 | E49: =IF(3<$C$24,0,$E$24*$D$24*(1+$C$27)*(1+$C$28)^0) -> 0 | F49: =IF(4<$C$24,0,$E$24*$D$24*(1+$C$27)*(1+$C$28)^0) -> 0 | G49: =IF(5<$C$24,0,$E$24*$D$24*(1+$C$27)*(1+$C$28)^0) -> 0 | H49: =IF(6<$C$24,0,$E$24*$D$24*(1+$C$27)*(1+$C$28)^0) -> 0 | I49: =IF(7<$C$24,0,$E$24*$D$24*(1+$C$27)*(1+$C$28)^0) -> 0 | J49: =IF(8<$C$24,0,$E$24*$D$24*(1+$C$27)*(1+$C$28)^0) -> 0 | K49: =IF(9<$C$24,0,$E$24*$D$24*(1+$C$27)*(1+$C$28)^0) -> 0 | L49: =IF(10<$C$24,0,$E$24*$D$24*(1+$C$27)*(1+$C$28)^0) -> 0 | M49: =IF(11<$C$24,0,$E$24*$D$24*(1+$C$27)*(1+$C$28)^0) -> 0 | N49: =IF(12<$C$24,0,$E$24*$D$24*(1+$C$27)*(1+$C$28)^0) -> 0 | O49: =IF(13<$C$24,0,$F$24*$D$24*(1+$C$27)*(1+$C$28)^1) -> 0 | P49: =IF(14<$C$24,0,$F$24*$D$24*(1+$C$27)*(1+$C$28)^1) -> 0 | Q49: =IF(15<$C$24,0,$F$24*$D$24*(1+$C$27)*(1+$C$28)^1) -> 0 | R49: =IF(16<$C$24,0,$F$24*$D$24*(1+$C$27)*(1+$C$28)^1) -> 0 | S49: =IF(17<$C$24,0,$F$24*$D$24*(1+$C$27)*(1+$C$28)^1) -> 0 | T49: =IF(18<$C$24,0,$F$24*$D$24*(1+$C$27)*(1+$C$28)^1) -> 0 | U49: =IF(19<$C$24,0,$F$24*$D$24*(1+$C$27)*(1+$C$28)^1) -> 0 | V49: =IF(20<$C$24,0,$F$24*$D$24*(1+$C$27)*(1+$C$28)^1) -> 0 | W49: =IF(21<$C$24,0,$F$24*$D$24*(1+$C$27)*(1+$C$28)^1) -> 0 | X49: =IF(22<$C$24,0,$F$24*$D$24*(1+$C$27)*(1+$C$28)^1) -> 0 | Y49: =IF(23<$C$24,0,$F$24*$D$24*(1+$C$27)*(1+$C$28)^1) -> 0 | Z49: =IF(24<$C$24,0,$F$24*$D$24*(1+$C$27)*(1+$C$28)^1) -> 0 | AA49: =IF(25<$C$24,0,$G$24*$D$24*(1+$C$27)*(1+$C$28)^2) -> 0 | AB49: =IF(26<$C$24,0,$G$24*$D$24*(1+$C$27)*(1+$C$28)^2) -> 0 | AC49: =IF(27<$C$24,0,$G$24*$D$24*(1+$C$27)*(1+$C$28)^2) -> 0 | AD49: =IF(28<$C$24,0,$G$24*$D$24*(1+$C$27)*(1+$C$28)^2) -> 0 | AE49: =IF(29<$C$24,0,$G$24*$D$24*(1+$C$27)*(1+$C$28)^2) -> 0 | AF49: =IF(30<$C$24,0,$G$24*$D$24*(1+$C$27)*(1+$C$28)^2) -> 0 | AG49: =IF(31<$C$24,0,$G$24*$D$24*(1+$C$27)*(1+$C$28)^2) -> 0 | AH49: =IF(32<$C$24,0,$G$24*$D$24*(1+$C$27)*(1+$C$28)^2) -> 0 | AI49: =IF(33<$C$24,0,$G$24*$D$24*(1+$C$27)*(1+$C$28)^2) -> 0 | AJ49: =IF(34<$C$24,0,$G$24*$D$24*(1+$C$27)*(1+$C$28)^2) -> 0 | AK49: =IF(35<$C$24,0,$G$24*$D$24*(1+$C$27)*(1+$C$28)^2) -> 0 | AL49: =IF(36<$C$24,0,$G$24*$D$24*(1+$C$27)*(1+$C$28)^2) -> 0 | AN49: =SUM(C49:N49) -> 0 | AO49: =SUM(O49:Z49) -> 0 | AP49: =SUM(AA49:AL49) -> 0
...

Sheet Actuals
A1: Actuals and Opening Position
A2: The money already in, the opening balance sheet it creates, and a grid to record each month as it closes so this becomes an operating tool rather than a one-off forecast.
A5: OPENING POSITION AT 30 SEPTEMBER 2026
A6: Cash at bank | B6: founder capital already contributed | C6: =Assumptions!$C$140 -> 50000
A7: Trade receivables | B7: nothing invoiced yet | C7: 0
A8: Property and equipment, net | B8: nothing acquired yet | C8: 0
A9: Intangible assets, net | B9: capitalised from month 1 | C9: 0
A10: Total opening assets | C10: =SUM(C6:C9) -> 50000
A12: Trade and other payables | B12: none at inception | C12: 0
A13: Paid-in share capital | B13: the opening cash, recorded as equity | C13: =Assumptions!$C$140 -> 50000
A14: Retained earnings | B14: no trading before month 1 | C14: 0
A15: Total opening liabilities and equity | C15: =C12+C13+C14 -> 50000
A16: CHECK — assets less liabilities and equity | B16: must read nil | C16: =C10-C15 -> 0
A18: MONTHLY ACTUALS — ENTER AS EACH MONTH CLOSES
A19: Leave a month blank until it has closed. Nothing downstream reads this grid: the statements run on the forecast, and these rows exist so the variance can be read without disturbing the model.
A20: Line item | B20: Driver / source | C20: Oct 26 | D20: Nov 26 | E20: Dec 26 | F20: Jan 26 | G20: Feb 26 | H20: Mar 26 | I20: Apr 26 | J20: May 26 | K20: Jun 26 | L20: Jul 27 | M20: Aug 27 | N20: Sep 27 | O20: Oct 27 | P20: Nov 27 | Q20: Dec 27 | R20: Jan 27 | S20: Feb 27 | T20: Mar 27 | U20: Apr 27 | V20: May 27 | W20: Jun 27 | X20: Jul 28 | Y20: Aug 28 | Z20: Sep 28 | AA20: Oct 28 | AB20: Nov 28 | AC20: Dec 28 | AD20: Jan 28 | AE20: Feb 28 | AF20: Mar 28 | AG20: Apr 28 | AH20: May 28 | AI20: Jun 28 | AJ20: Jul 29 | AK20: Aug 29 | AL20: Sep 29 | AN20: YEAR 1 | AO20: YEAR 2 | AP20: YEAR 3
A21: Revenue — actual | B21: enter when the month closes | AN21: =SUM(C21:N21) -> 0 | AO21: =SUM(O21:Z21) -> 0 | AP21: =SUM(AA21:AL21) -> 0
A22: Direct cost — actual | B22: enter when the month closes | AN22: =SUM(C22:N22) -> 0 | AO22: =SUM(O22:Z22) -> 0 | AP22: =SUM(AA22:AL22) -> 0
A23: Operating cost — actual | B23: enter when the month closes | AN23: =SUM(C23:N23) -> 0 | AO23: =SUM(O23:Z23) -> 0 | AP23: =SUM(AA23:AL23) -> 0
A24: Closing cash — actual | B24: enter when the month closes | AN24: =SUM(C24:N24) -> 0 | AO24: =SUM(O24:Z24) -> 0 | AP24: =SUM(AA24:AL24) -> 0
A26: VARIANCE AGAINST THE MODEL
A27: Line item | B27: Driver / source | C27: Oct 26 | D27: Nov 26 | E27: Dec 26 | F27: Jan 26 | G27: Feb 26 | H27: Mar 26 | I27: Apr 26 | J27: May 26 | K27: Jun 26 | L27: Jul 27 | M27: Aug 27 | N27: Sep 27 | O27: Oct 27 | P27: Nov 27 | Q27: Dec 27 | R27: Jan 27 | S27: Feb 27 | T27: Mar 27 | U27: Apr 27 | V27: May 27 | W27: Jun 27 | X27: Jul 28 | Y27: Aug 28 | Z27: Sep 28 | AA27: Oct 28 | AB27: Nov 28 | AC27: Dec 28 | AD27: Jan 28 | AE27: Feb 28 | AF27: Mar 28 | AG27: Apr 28 | AH27: May 28 | AI27: Jun 28 | AJ27: Jul 29 | AK27: Aug 29 | AL27: Sep 29 | AN27: YEAR 1 | AO27: YEAR 2 | AP27: YEAR 3
A28: Revenue — forecast | B28: from the model | C28: =Revenue!C$49 -> 2340.7128 | D28: =Revenue!D$49 -> 2656.9074 | E28: =Revenue!E$49 -> 3048.7445 | F28: =Revenue!F$49 -> 23738.958 | G28: =Revenue!G$49 -> 26202.103 | H28: =Revenue!H$49 -> 29448.491 | I28: =Revenue!I$49 -> 48411.774 | J28: =Revenue!J$49 -> 53317.397 | ... AL28: =Revenue!AL$49 -> 672449.28 | AN28: =SUM(C28:N28) -> 614990.61 | AO28: =SUM(O28:Z28) -> 2786041.1 | AP28: =SUM(AA28:AL28) -> 6112588
A29: Revenue — variance | B29: blank months read as nil | C29: =IF(C21=0,0,C21-C28) -> 0 | D29: =IF(D21=0,0,D21-D28) -> 0 | E29: =IF(E21=0,0,E21-E28) -> 0 | F29: =IF(F21=0,0,F21-F28) -> 0 | G29: =IF(G21=0,0,G21-G28) -> 0 | H29: =IF(H21=0,0,H21-H28) -> 0 | I29: =IF(I21=0,0,I21-I28) -> 0 | J29: =IF(J21=0,0,J21-J28) -> 0 | ... AL29: =IF(AL21=0,0,AL21-AL28) -> 0 | AN29: =SUM(C29:N29) -> 0 | AO29: =SUM(O29:Z29) -> 0 | AP29: =SUM(AA29:AL29) -> 0
