Workbook

Sheet Cover
B2: Coremerce
B3: Operational Financial Model and Valuation, 2027 to 2031
B6: ABOUT THIS MODEL
B7: Business name | D7: Coremerce
B8: Industry | D8: Cloud commerce software: online stores, point of sale, inventory, payments and analytics for merchants
B9: Markets | D9: Egypt, with the platform built in English and Arabic
B10: Products | D10: Four plans: Launch (free), Starter, Pro and Enterprise, with a transaction fee on online payments
B11: Model currency | D11: USD, with Egyptian pound prices and costs converted at a monthly rate on the Timeline and FX sheet
B12: Model start | C12: date | D12: January 2027
B13: Months in a period | C13: months | D13: 12
B14: Forecast period | C14: years | D14: 5
B15: Total months modeled | C15: months | D15: 60
B17: HOW TO READ IT
B18: Blue figures on a yellow fill are typed inputs. Change those and the whole model moves.
B19: Black figures are formulas on the same sheet. Green figures are links to another sheet.
B20: Red figures are checks. The balance sheet check must read nil in every column.
B21: On every time sheet the year total comes first, then that year's twelve months.
B22: No volume is typed. Free stores, paying accounts and transaction value are produced by the account engine, so cut the activity and the volume goes with it.
B23: The year one spend is an output of the Expenses sheet, not a ceiling anybody typed. The funding ask is built from all twelve months of it on the Funding and Use of Funds sheet.
B25: CONTENTS
B26: Cover | D26: This page: what the model is and how to read it
B27: Summary | D27: The whole model on one page
B28: Market Research | D28: The market the model sells into, and who else is in it
B29: Old Study Corrections | D29: What was wrong in the earlier feasibility study, and what this model does instead
B30: Input
B31: Assumption Setting | D31: In the order the model runs: basis, opening position, acquisition, the funnels, capacity, pricing, expense
B32: Capital Expenditure | D32: Assets driven by new hires, plus shared and intangible assets
B33: Actuals | D33: The opening position and a grid to record each month
B34: Process
B35: Timeline and FX | D35: The calendar, the pound rate and the cost indices
B36: Acquisitions | D36: Spend to activity to signups to paying accounts, sixty months
B37: GTM Capacity and Timing | D37: Who runs the activity, whether there are enough of them, and how long a deal takes
B38: Revenue Streams | D38: Eight engines, every one of them an output of the account engine
B39: Total Revenue | D39: Gathered into four families
B40: Payroll | D40: Roles monthly, with heads set by year
B41: Depreciation and Amortization | D41: Straight line by asset class
B42: Expenses | D42: Direct cost, revenue share, operating cost, and the first twelve months in full
B43: Output
B44: Income Statement | D44: Five years to 31 December
B45: Balance Sheet | D45: Five years, with the balance check
...

Sheet Summary
A1: Summary
A2: The whole model on one page.
A4: HEADLINES
C5: Year 1 | D5: Year 2 | E5: Year 3 | F5: Year 4 | G5: Year 5
A6: Total revenue | C6: ='Financial Indicators'!C6 -> 68602.054 | D6: ='Financial Indicators'!D6 -> 391860.51 | E6: ='Financial Indicators'!E6 -> 1221612.7 | F6: ='Financial Indicators'!F6 -> 2763830.2 | G6: ='Financial Indicators'!G6 -> 4998712.1
A7: Gross profit | C7: ='Financial Indicators'!C25 -> 52349.611 | D7: ='Financial Indicators'!D25 -> 311491.05 | E7: ='Financial Indicators'!E25 -> 993713.54 | F7: ='Financial Indicators'!F25 -> 2279092.2 | G7: ='Financial Indicators'!G25 -> 4154745.5
A8: Gross margin | C8: ='Financial Indicators'!C26 -> 0.76309101 | D8: ='Financial Indicators'!D26 -> 0.79490288 | E8: ='Financial Indicators'!E26 -> 0.81344401 | F8: ='Financial Indicators'!F26 -> 0.82461369 | G8: ='Financial Indicators'!G26 -> 0.83116318
A9: EBITDA | C9: ='Financial Indicators'!C27 -> -403637.77 | D9: ='Financial Indicators'!D27 -> -440831.34 | E9: ='Financial Indicators'!E27 -> -168454.15 | F9: ='Financial Indicators'!F27 -> 618842.26 | G9: ='Financial Indicators'!G27 -> 1844005.9
A10: Net profit | C10: ='Financial Indicators'!C29 -> -429039.21 | D10: ='Financial Indicators'!D29 -> -471650.56 | E10: ='Financial Indicators'!E29 -> -205902.53 | F10: ='Financial Indicators'!F29 -> 586091.55 | G10: ='Financial Indicators'!G29 -> 1518916.5
A11: Total expenses, direct and operating | C11: ='Financial Indicators'!C31 -> 497641.26 | D11: ='Financial Indicators'!D31 -> 863511.07 | E11: ='Financial Indicators'!E31 -> 1427515.2 | F11: ='Financial Indicators'!F31 -> 2177738.6 | G11: ='Financial Indicators'!G31 -> 3189932.9
A12: Cash at year end | C12: ='Financial Indicators'!C47 -> 185235.3 | D12: ='Financial Indicators'!D47 -> 237273.56 | E12: ='Financial Indicators'!E47 -> 188317.95 | F12: ='Financial Indicators'!F47 -> 1031867.6 | G12: ='Financial Indicators'!G47 -> 3195853.7
A13: Lowest cash balance in the year | C13: ='Financial Indicators'!C48 -> 185235.3 | D13: ='Financial Indicators'!D48 -> 237273.56 | E13: ='Financial Indicators'!E48 -> 118602.47 | F13: ='Financial Indicators'!F48 -> 244212.67 | G13: ='Financial Indicators'!G48 -> 1209507
A14: Employees at year end | C14: ='Financial Indicators'!C17 -> 24 | D14: ='Financial Indicators'!D17 -> 40 | E14: ='Financial Indicators'!E17 -> 60 | F14: ='Financial Indicators'!F17 -> 84 | G14: ='Financial Indicators'!G17 -> 115
A15: Paying accounts at year end | C15: ='Financial Indicators'!C15 -> 319.89518 | D15: ='Financial Indicators'!D15 -> 1234.8023 | E15: ='Financial Indicators'!E15 -> 3089.9291 | F15: ='Financial Indicators'!F15 -> 6004.4174 | G15: ='Financial Indicators'!G15 -> 9567.5154
A16: Launch (free) stores at year end | C16: ='Financial Indicators'!C11 -> 4207.4483 | D16: ='Financial Indicators'!D11 -> 12270 | E16: ='Financial Indicators'!E11 -> 24195.606 | F16: ='Financial Indicators'!F11 -> 37855.297 | G16: ='Financial Indicators'!G11 -> 52258.036
A17: Annualised recurring revenue at year end | C17: ='Financial Indicators'!C20 -> 107448.12 | D17: ='Financial Indicators'!D20 -> 443128.98 | E17: ='Financial Indicators'!E20 -> 1183326.9 | F17: ='Financial Indicators'!F20 -> 2411636.9 | G17: ='Financial Indicators'!G20 -> 4019403.3
A18: Online payment value processed | C18: ='Financial Indicators'!C21 -> 1105450.2 | D18: ='Financial Indicators'!D21 -> 6826394.2 | E18: ='Financial Indicators'!E21 -> 22838228 | F18: ='Financial Indicators'!F21 -> 55358175 | G18: ='Financial Indicators'!G21 -> 1.056398e+08
A19: Cost per new paying account, fully loaded | C19: ='Financial Indicators'!C37 -> 323.43627 | D19: ='Financial Indicators'!D37 -> 221.42482 | E19: ='Financial Indicators'!E37 -> 175.50587 | F19: ='Financial Indicators'!F37 -> 161.43406 | G19: ='Financial Indicators'!G37 -> 171.06171
A20: LTV to CAC | C20: ='Financial Indicators'!C41 -> 2.0657785 | D20: ='Financial Indicators'!D41 -> 4.182758 | E20: ='Financial Indicators'!E41 -> 6.8208769 | F20: ='Financial Indicators'!F41 -> 8.9767299 | G20: ='Financial Indicators'!G41 -> 9.9457682
A22: THE CHECKS THAT MATTER
A23: Year one total expense, produced not typed | C23: =Expenses!$C$93 -> 497641.26
A24: Balance sheet check, must read nil in every column | C24: ='Balance Sheet'!C23 -> 0 | D24: ='Balance Sheet'!D23 -> 0 | E24: ='Balance Sheet'!E23 -> 0 | F24: ='Balance Sheet'!F23 -> 0 | G24: ='Balance Sheet'!G23 -> 0
A25: Months with a capacity shortfall across the five years, must read nil | C25: =SUM('GTM Capacity and Timing'!$C$25:$BN$25)-SUM('GTM Capacity and Timing'!$B$25,'GTM Capacity and Timing'!$O$25,'GTM Capacity and Timing'!$AB$25,'GTM Capacity and Timing'!$AO$25,'GTM Capacity and Timing'!$BB$25) -> 0
A26: Year one cost categories reconcile to the Expenses sheet, must read nil | C26: ='Funding and Use of Funds'!$C$25 -> 0
A28: WHAT THIS MODEL OPENS ON
A29: Active Launch (free) stores | B29: on the platform at 31 December 2026 | C29: ='Assumption Setting'!$C$13 -> 0
A30: Paying Starter accounts | B30: the honest starting point for the subscription engine | C30: ='Assumption Setting'!$C$14 -> 0
A31: Paying Pro accounts | C31: ='Assumption Setting'!$C$15 -> 0
A32: Paying Enterprise accounts | C32: ='Assumption Setting'!$C$16 -> 0
A33: Opening cash | B33: founder capital already contributed | C33: ='Assumption Setting'!$C$17 -> 0
A34: Founder capital spent on the product | B34: carried as an intangible | C34: ='Assumption Setting'!$C$20 -> 58252.427
A36: THE ASK
A37: Seed round sought | C37: ='Funding and Use of Funds'!$C$9 -> 600000
A38: Total cash required in year one, expense and capital | C38: ='Funding and Use of Funds'!$C$5 -> 518418.99
A39: Months of year one spend this round funds | C39: ='Funding and Use of Funds'!$C$12 -> 13.88838
A40: Year one covered in full | C40: ='Funding and Use of Funds'!$C$13 -> Covered
A41: Second round needed after the seed | C41: ='Funding and Use of Funds'!$C$49 -> 450000
A42: Weighted pre money valuation | C42: =Valuation!$C$93 -> 1307992.6
A43: Pre money valuation asked | C43: =Valuation!$C$98 -> 1300000
A44: What the seed buys | C44: =Valuation!$C$100 -> 0.31578947

Sheet Market Research
A1: Market Research
A2: The sector the model sells into. No revenue in this model is attributed to any single name below. Figures are as reported by the sources named and have not been audited.
A4: THE MARKET THE MODEL SELLS INTO
A5: Measure | B5: Figure | C5: Basis | D5: Source
A6: Egypt ecommerce market size, 2025 | B6: USD 9.9 billion; USD 2.3 billion on a narrower definition | C6: Counted, definitions differ by a factor of four | D6: ResearchAndMarkets via ValueSpectrum, January 2026; ECDB
A7: Egypt ecommerce market size, 2024 | B7: USD 9.1 billion | C7: Counted | D7: PS Market Research
A8: Growth outlook | B8: About 10 per cent a year, to USD 14.5 billion by 2029 | C8: Projected | D8: ResearchAndMarkets, 10.0 per cent CAGR; PS Market Research 10.2 per cent to 2032
A9: Cash on delivery share of online orders | B9: 45 per cent of the payment market in 2024; 55 to 70 per cent of shoppers prefer it | C9: Counted, one source | D9: PS Market Research
A10: Financial inclusion | B10: 74.8 per cent of eligible Egyptians at end 2024 | C10: Counted, one source | D10: Reported in 2026 Egypt ecommerce statistics roundups, primary source not confirmed
A11: Micro, small and medium enterprises | B11: 98 per cent of private enterprises | C11: Counted | D11: Al Ahram, citing the United Nations
A12: Small and medium firms that sell online | B12: About 3 per cent, older government estimate | C12: Counted, undated | D12: Bank of Scotland Trade market potential page
A13: Social sellers in Egypt | B13: Nearly 1.3 million | C13: Counted, vendor survey, Q1 2022 | D13: Market research summary of a global survey
A14: Facebook active accounts in Egypt | B14: More than 44 million, February 2022 | C14: Counted | D14: Academic paper citing Kemp 2022
A15: Urban consumer price inflation | B15: 14.9 per cent in July 2026 | C15: Counted | D15: CAPMAS, reported by Daily News Egypt
A16: Egyptian pounds to the dollar | B16: 50.96 to 52.5 across sources in mid 2026 | C16: Counted | D16: Pluang, Wise and CurrencyConvert snapshots
... A18: Regional startup funding, first half 2026 | B18: USD 1.7 billion across MENA; Egypt USD 86 million in Q1 | C18: Counted | D18: Wamda, Arab News
A20: WHO ELSE IS IN THIS MARKET
A21: Company | B21: Position | C21: Funding | D21: What it means for Coremerce
A22: Shopify | B22: Global leader in hosted commerce, listed | C22: Listed, about 13.9 times revenue on one screener | D22: Sets the feature and price reference. Weak on Arabic, cash on delivery and local payments
A23: Salla | B23: Saudi commerce platform, over 80,000 active merchants at the 2024 round | C23: USD 130 million pre IPO round, March 2024, Investcorp and Sanabil | D23: The regional leader. The natural entrant into Egypt, and the natural buyer
A24: Zid | B24: Saudi commerce platform | C24: USD 7 million Series A, 2021; USD 50 million Series B led by IMPACT46 | D24: A funded Gulf peer with the same plan structure
A25: ExpandCart | B25: Egyptian commerce platform | C25: USD 2.5 million Series A led by Sawari Ventures; a USD 2.7 million pre Series B led by Betatron is also reported | D25: The closest Egyptian like for like
A26: Wuilt | B26: Egyptian store builder | C26: USD 2 million, August 2025, Flat6Labs and MTF VC | D26: Dropped subscription fees in April 2025 and earns on shipping, payments and wallet. Proof that free is the pressure on the Launch to paid path
A27: Paymob | B27: Egyptian payments | C27: USD 50 million Series B, May 2022, Kora, PayPal Ventures and Clay Point | D27: The likely payments partner, and a possible acquirer of merchant volume
A28: Wix | B28: Website and commerce platform, listed | C28: Listed, about 4.7 times revenue in 2025 | D28: A mature reference multiple
A29: Commerce.com, formerly BigCommerce | B29: Mid market commerce platform, listed | C29: Listed, about 0.7 times revenue in July 2026 | D29: The floor multiple when growth stalls
A31: Coremerce's own site claims 10,000 plus businesses in 40 plus countries and 99.9 per cent uptime. These claims are not verified and drive nothing in this model.
A32: No revenue in this model is attributed to any one of these companies. They are listed so the competitive position is visible.

Sheet Old Study Corrections
A1: Old Study Corrections
A2: What was wrong in the earlier feasibility study of the USD 200,000 round, the effect, and what this model does instead.
A4: ERRORS AND OMISSIONS FOUND
A5: No | B5: Where in the old study | C5: What was wrong | D5: Effect | E5: What this model does
A6: 1 | B6: Prices and rate | C6: The annual Starter price of EGP 9,600 was divided by 48 to give USD 200, then every figure was converted back at 52. | D6: Pound revenue overstated by 8.3 per cent on every paying account. | E6: Prices are typed in pounds from the public price page and converted at one stated monthly rate.
A7: 2 | B7: Revenue timing, year one | C7: Year one revenue was year end accounts times the full annual price, less one month. | D7: Treats every account as paying for the whole year. Accounts arrive through the year, so average accounts are about half the year end figure. | E7: Revenue is average accounts in each month times the monthly price, for sixty months.
A8: 3 | B8: Revenue timing, later years | C8: Years two to five used year end accounts times the full price. | D8: Overstates revenue by the growth in accounts across the year, about 40 per cent in year two. | E8: Same monthly engine, so growth is recognised as it happens.
A9: 4 | B9: Revenue lines missing | C9: Enterprise had no price and no revenue. Transaction fees of 2 and 1 per cent, extra stores and every add on were left out. | D9: Understates the upside and hides what the paid plans really earn. | E9: Enterprise, transaction fees, extra stores and three roadmap engines are modeled, each with an opening month.
A10: 5 | B10: No cost of revenue | C10: Other expenses were set to zero. Hosting, AI inference, messaging, collection costs and partner shares were all missing. | D10: A gross margin of 100 per cent and a free tier that cost nothing to run. | E10: Ten direct cost lines driven by accounts and revenue, including the free stores.
A11: 6 | B11: Salaries frozen | C11: Salary growth was zero for five years and the insurance ceiling stayed at EGP 16,700. | D11: Payroll understated every year as inflation runs near 15 per cent and the ceiling rises each January. | E11: Annual increase of 12 per cent and a ceiling that steps up each year, both inputs.
A12: 7 | B12: Equipment | C12: EGP 1.53 million of kit was charged in full before launch and never depreciated. | D12: No balance sheet asset, no depreciation, and the kit was not tied to hiring. | E12: Kits follow each hire, and every asset class is depreciated straight line.
A13: 8 | B13: No statements | C13: There was no balance sheet, no cash flow and no working capital. | D13: Cumulative profit was treated as cash. Receivables, payables and annual prepayments were ignored. | E13: Full income statement, balance sheet and monthly cash flow, with a check that must read nil.
A14: 9 | B14: Marketing held flat | C14: Marketing stayed at USD 50,000 a year for five years while paying merchants grew sevenfold. | D14: Either the growth is unfunded or the budget is wrong. | E14: Channel budgets rise by year, and every channel has a cost per click and a conversion.
A15: 10 | B15: Cost of acquiring a customer | C15: Cost per account was a simple average of four channels instead of a budget weighted average. | D15: Understated the weighted cost: 26.25 per cent of price instead of 30 per cent, and USD 4.50 instead of USD 5.20 per free account. | E15: Signups come from clicks and conversions per channel, and cost per new paying account is measured, not assumed.
A16: 11 | B16: Budget split | C16: The marketing budget was split one third each across free, Starter and Pro regardless of channel mix. | D16: Allocation was arbitrary and fixed the mix of plans. | E16: Plan mix comes from trial starts, trial conversion, direct sales and upgrades.
A17: 12 | B17: Churn and upgrades | C17: Churn and the 15 per cent upgrade rate were applied once a year to opening plus new accounts. | D17: Ignores when accounts join and leave. | E17: Monthly churn and upgrade rates by plan and by year.
... A23: 18 | B23: Dates and symbols | C23: The start date was October 2026 and the text carried check marks, arrows, bullets and en dashes. | D23: The start has passed. Symbols do not belong in a model sent to investors. | E23: The model starts January 2027 and carries plain text only.
A25: HEADLINE COMPARISON, OLD STUDY AGAINST THIS MODEL
B26: Measure | C26: Old study | D26: This model | E26: Comment
B27: Seed ask, USD | C27: 200000 | D27: ='Funding and Use of Funds'!$C$9 -> 600000 | E27: The new ask covers all twelve months of year one spend
B28: Year one revenue, USD | C28: 212143 | D28: ='Total Revenue'!B18 -> 68602.054 | E28: The old figure used year end accounts for the whole year
B29: Year five revenue, USD | C29: 1924676 | D29: ='Total Revenue'!BB18 -> 4998712.1
B30: Year five net profit, USD | C30: 1217332 | D30: ='Income Statement'!$G$53 -> 1518916.5 | E30: The old figure had no cost of revenue and frozen salaries
B31: Paying merchants at the end of year five | C31: 6313 | D31: =Acquisitions!BB124 -> 9567.5154
B32: Pre money valuation, USD | C32: 1800000 | D32: =Valuation!$C$98 -> 1300000 | E32: The old figure was the ask divided by 10 per cent less the ask
B34: Old study figures are typed as read from the earlier file. Net profit and paying merchants for the old study are from its sales and study sheets.

Sheet Input>>
B2: Input
B5: Assumption Setting | C5: In the order the model runs: basis, opening position, acquisition, the funnels, capacity, pricing, expense
B6: Capital Expenditure | C6: Assets driven by new hires, plus shared and intangible assets
B7: Actuals | C7: The opening position and a grid to record each month

Sheet Assumption Setting
A1: Assumption Setting
A2: Everything typed in this model is on this sheet, apart from the establishment table on Payroll and the grid on Actuals. Nothing downstream is a typed number.
A4: 1. MODEL BASIS
A5: Reporting currency | C5: USD
A6: First calendar month of the model | C6: 46388
A7: Egyptian pounds to the dollar at the start | B7: EGP | C7: 51.5 | D7: Spot sources in mid 2026 range from 50.96 to 52.5. Change it here and every pound input converts.
A8: Annual change in the pound against the dollar | B8: % | C8: 0.06 | D8: A steady slide of 6 per cent a year. Pound prices and costs convert at the monthly rate this produces.
A9: Prices and revenue are stated net of VAT. VAT collected is passed to the tax authority and is not modeled. No interest is earned on cash and no dividends are paid.
A11: 2. THE OPENING POSITION, WHAT IS ALREADY TRUE
A12: Placeholders to be replaced with the company's own figures at 31 December 2026. The site claims 10,000 plus businesses; this model does not rely on that claim and opens at zero.
A13: Active Launch (free) stores on the platform | B13: # | C13: 0
A14: Paying Starter accounts | B14: # | C14: 0
A15: Paying Pro accounts | B15: # | C15: 0
A16: Paying Enterprise accounts | B16: # | C16: 0
A17: Opening cash at 31 December 2026 | B17: USD | C17: 0
A18: Paid in share capital at inception, cash, equal to opening cash | B18: USD | C18: =C17 -> 0
A19: Founder capital already spent building the product | B19: EGP | C19: 3000000 | D19: EGP 3.0 million, from the earlier feasibility study. Carried as an intangible and amortised.
A20: The same, in dollars at the opening rate | B20: USD | C20: =C19/C7 -> 58252.427
A22: 3. ACQUISITION, ONLINE CHANNELS
A23: Budget divided by cost per click gives paid clicks. Organic and referral visits are a stated share of paid. Visits times click to signup gives free accounts created.
A24: Online channel, monthly budget | B24: Unit | C24: Budget Y1 | D24: Y2 | E24: Y3 | F24: Y4 | G24: Y5 | H24: Cost per click | I24: Organic % of paid | J24: Referral % of paid | K24: Click to signup
A25: Meta and Instagram ads, merchants | B25: USD | C25: 800 | D25: 2000 | E25: 3600 | F25: 5200 | G25: 6800 | H25: 0.1 | I25: 0.22 | J25: 0.07 | K25: 0.026
A26: Google Search, store builder and POS intent | B26: USD | C26: 500 | D26: 1300 | E26: 2300 | F26: 3300 | G26: 4300 | H26: 0.22 | I26: 0.1 | J26: 0.03 | K26: 0.05
A27: TikTok and short video, sellers | B27: USD | C27: 300 | D27: 700 | E27: 1300 | F27: 1900 | G27: 2400 | H27: 0.06 | I27: 0.3 | J27: 0.09 | K27: 0.014
A28: Retargeting, trial starters | B28: USD | C28: 200 | D28: 450 | E28: 800 | F28: 1100 | G28: 1400 | H28: 0.14 | I28: 0.04 | J28: 0.02 | K28: 0.07
A29: Content and SEO, Arabic commerce guides | B29: USD | C29: 833 | D29: 1500 | E29: 2400 | F29: 3200 | G29: 4000 | H29: 0.3 | I29: 0.3 | J29: 0.05 | K29: 0.03
A30: Merchant referral program credits | B30: USD | C30: 417 | D30: 900 | E30: 1500 | F30: 2100 | G30: 2700 | H30: 0.45 | I30: 0 | J30: 0.04 | K30: 0.1
A31: Seller communities and social groups | B31: USD | C31: 300 | D31: 650 | E31: 1100 | F31: 1500 | G31: 1900 | H31: 0.12 | I31: 0.12 | J31: 0.04 | K31: 0.035
A33: Online advertising cost | B33: Unit | C33: Year 1 | D33: Year 2 | E33: Year 3 | F33: Year 4 | G33: Year 5
A34: Annual rise in cost per click as budgets scale | B34: % | C34: 0 | D34: 0.1 | E34: 0.1 | F34: 0.1 | G34: 0.1 | H34: Auction prices rise with spend and with Egyptian inflation
A35: Cumulative cost per click index | B35: x | C35: =1+C34 -> 1 | D35: =C35*(1+D34) -> 1.1 | E35: =D35*(1+E34) -> 1.21 | F35: =E35*(1+F34) -> 1.331 | G35: =F35*(1+G34) -> 1.4641
A37: Signup quality and the self serve path | B37: Unit | C37: Year 1 | D37: Year 2 | E37: Year 3 | F37: Year 4 | G37: Year 5
A38: Signups on the free path who create a store | B38: % | C38: 0.38 | D38: 0.4 | E38: 0.42 | F38: 0.43 | G38: 0.44
A39: Signups who start a Starter trial | B39: % | C39: 0.07 | D39: 0.08 | E39: 0.09 | F39: 0.1 | G39: 0.1
A40: Signups who start a Pro trial | B40: % | C40: 0.015 | D40: 0.02 | E40: 0.025 | F40: 0.03 | G40: 0.03
A41: Signups who book a demo with sales | B41: % | C41: 0.03 | D41: 0.035 | E41: 0.04 | F41: 0.04 | G41: 0.04
A42: Starter trial to paid, after the 14 day trial | B42: % | C42: 0.22 | D42: 0.24 | E42: 0.26 | F42: 0.27 | G42: 0.28
A43: Pro trial to paid, after the 14 day trial | B43: % | C43: 0.28 | D43: 0.3 | E43: 0.32 | F43: 0.33 | G43: 0.34
A44: Unconverted trials that stay on the free Launch plan | B44: % | C44: 0.5 | D44: 0.5 | E44: 0.5 | F44: 0.5 | G44: 0.5
A46: 4. ACQUISITION, OFFLINE ACTIVITY
...

Sheet Capital Expenditure
A1: Capital Expenditure
A2: Assets driven by new hires, plus shared and intangible assets. Cost in pounds, converted at the rate of the month it is bought.
A3: Month number | B3: 9999 | C3: 1 | D3: 2 | E3: 3 | F3: 4 | G3: 5 | H3: 6 | I3: 7 | J3: 8 | K3: 9 | L3: 10 | M3: 11 | N3: 12 | O3: 9999 | P3: 13 | Q3: 14 | R3: 15 | S3: 16 | T3: 17 | U3: 18 | V3: 19 | W3: 20 | X3: 21 | Y3: 22 | Z3: 23 | AA3: 24 | AB3: 9999 | AC3: 25 | AD3: 26 | AE3: 27 | AF3: 28 | AG3: 29 | AH3: 30 | AI3: 31 | AJ3: 32 | AK3: 33 | AL3: 34 | AM3: 35 | AN3: 36 | AO3: 9999 | AP3: 37 | AQ3: 38 | AR3: 39 | AS3: 40 | AT3: 41 | AU3: 42 | AV3: 43 | AW3: 44 | AX3: 45 | AY3: 46 | AZ3: 47 | BA3: 48 | BB3: 9999 | BC3: 49 | BD3: 50 | BE3: 51 | BF3: 52 | BG3: 53 | BH3: 54 | BI3: 55 | BJ3: 56 | BK3: 57 | BL3: 58 | BM3: 59 | BN3: 60
A4: ASSET PURCHASES, USD
A5: Asset class | B5: Year 1 | C5: Jan 27 | D5: Feb 27 | E5: Mar 27 | F5: Apr 27 | G5: May 27 | H5: Jun 27 | I5: Jul 27 | J5: Aug 27 | K5: Sep 27 | L5: Oct 27 | M5: Nov 27 | N5: Dec 27 | O5: Year 2 | P5: Jan 28 | Q5: Feb 28 | R5: Mar 28 | S5: Apr 28 | T5: May 28 | U5: Jun 28 | V5: Jul 28 | W5: Aug 28 | X5: Sep 28 | Y5: Oct 28 | Z5: Nov 28 | AA5: Dec 28 | AB5: Year 3 | AC5: Jan 29 | AD5: Feb 29 | AE5: Mar 29 | AF5: Apr 29 | AG5: May 29 | AH5: Jun 29 | AI5: Jul 29 | AJ5: Aug 29 | AK5: Sep 29 | AL5: Oct 29 | AM5: Nov 29 | AN5: Dec 29 | AO5: Year 4 | AP5: Jan 30 | AQ5: Feb 30 | AR5: Mar 30 | AS5: Apr 30 | AT5: May 30 | AU5: Jun 30 | AV5: Jul 30 | AW5: Aug 30 | AX5: Sep 30 | AY5: Oct 30 | AZ5: Nov 30 | BA5: Dec 30 | BB5: Year 5 | BC5: Jan 31 | BD5: Feb 31 | BE5: Mar 31 | BF5: Apr 31 | BG5: May 31 | BH5: Jun 31 | BI5: Jul 31 | BJ5: Aug 31 | BK5: Sep 31 | BL5: Oct 31 | BM5: Nov 31 | BN5: Dec 31
A6: Employee kits, laptop, monitor and phone | B6: =SUM(C6:N6) -> 29689.32 | C6: =(Payroll!C76*'Assumption Setting'!$C$201+Payroll!C75*'Assumption Setting'!$C$202)*(1+'Assumption Setting'!$C$203)/'Timeline and FX'!C8 -> 29689.32 | D6: =(Payroll!D76*'Assumption Setting'!$C$201+Payroll!D75*'Assumption Setting'!$C$202)*(1+'Assumption Setting'!$C$203)/'Timeline and FX'!D8 -> 0 | E6: =(Payroll!E76*'Assumption Setting'!$C$201+Payroll!E75*'Assumption Setting'!$C$202)*(1+'Assumption Setting'!$C$203)/'Timeline and FX'!E8 -> 0 | F6: =(Payroll!F76*'Assumption Setting'!$C$201+Payroll!F75*'Assumption Setting'!$C$202)*(1+'Assumption Setting'!$C$203)/'Timeline and FX'!F8 -> 0 | G6: =(Payroll!G76*'Assumption Setting'!$C$201+Payroll!G75*'Assumption Setting'!$C$202)*(1+'Assumption Setting'!$C$203)/'Timeline and FX'!G8 -> 0 | H6: =(Payroll!H76*'Assumption Setting'!$C$201+Payroll!H75*'Assumption Setting'!$C$202)*(1+'Assumption Setting'!$C$203)/'Timeline and FX'!H8 -> 0 | I6: =(Payroll!I76*'Assumption Setting'!$C$201+Payroll!I75*'Assumption Setting'!$C$202)*(1+'Assumption Setting'!$C$203)/'Timeline and FX'!I8 -> 0 | J6: =(Payroll!J76*'Assumption Setting'!$C$201+Payroll!J75*'Assumption Setting'!$C$202)*(1+'Assumption Setting'!$C$203)/'Timeline and FX'!J8 -> 0 | ... N6: =(Payroll!N76*'Assumption Setting'!$C$201+Payroll!N75*'Assumption Setting'!$C$202)*(1+'Assumption Setting'!$C$203)/'Timeline and FX'!N8 -> 0 | O6: =SUM(P6:AA6) -> 16819.8 | P6: =(Payroll!P76*'Assumption Setting'!$C$201+Payroll!P75*'Assumption Setting'!$C$202)*(1+'Assumption Setting'!$C$203)/'Timeline and FX'!P8 -> 13218.538 | Q6: =(Payroll!Q76*'Assumption Setting'!$C$201+Payroll!Q75*'Assumption Setting'!$C$202)*(1+'Assumption Setting'!$C$203)/'Timeline and FX'!Q8 -> 0 | R6: =(Payroll!R76*'Assumption Setting'!$C$201+Payroll!R75*'Assumption Setting'!$C$202)*(1+'Assumption Setting'!$C$203)/'Timeline and FX'!R8 -> 0 | S6: =(Payroll!S76*'Assumption Setting'!$C$201+Payroll!S75*'Assumption Setting'!$C$202)*(1+'Assumption Setting'!$C$203)/'Timeline and FX'!S8 -> 0 | T6: =(Payroll!T76*'Assumption Setting'!$C$201+Payroll!T75*'Assumption Setting'!$C$202)*(1+'Assumption Setting'!$C$203)/'Timeline and FX'!T8 -> 909.08006 | U6: =(Payroll!U76*'Assumption Setting'!$C$201+Payroll!U75*'Assumption Setting'!$C$202)*(1+'Assumption Setting'!$C$203)/'Timeline and FX'!U8 -> 0 | V6: =(Payroll!V76*'Assumption Setting'!$C$201+Payroll!V75*'Assumption Setting'!$C$202)*(1+'Assumption Setting'!$C$203)/'Timeline and FX'!V8 -> 1800.5886 | W6: =(Payroll!W76*'Assumption Setting'!$C$201+Payroll!W75*'Assumption Setting'!$C$202)*(1+'Assumption Setting'!$C$203)/'Timeline and FX'!W8 -> 0 | ... AA6: =(Payroll!AA76*'Assumption Setting'!$C$201+Payroll!AA75*'Assumption Setting'!$C$202)*(1+'Assumption Setting'!$C$203)/'Timeline and FX'!AA8 -> 0 | AB6: =SUM(AC6:AN6) -> 20303.972 | AC6: =(Payroll!AC76*'Assumption Setting'!$C$201+Payroll!AC75*'Assumption Setting'!$C$202)*(1+'Assumption Setting'!$C$203)/'Timeline and FX'!AC8 -> 15207.706 | AD6: =(Payroll!AD76*'Assumption Setting'!$C$201+Payroll!AD75*'Assumption Setting'!$C$202)*(1+'Assumption Setting'!$C$203)/'Timeline and FX'!AD8 -> 0 | AE6: =(Payroll!AE76*'Assumption Setting'!$C$201+Payroll!AE75*'Assumption Setting'!$C$202)*(1+'Assumption Setting'!$C$203)/'Timeline and FX'!AE8 -> 0 | AF6: =(Payroll!AF76*'Assumption Setting'!$C$201+Payroll!AF75*'Assumption Setting'!$C$202)*(1+'Assumption Setting'!$C$203)/'Timeline and FX'!AF8 -> 861.79722 | AG6: =(Payroll!AG76*'Assumption Setting'!$C$201+Payroll!AG75*'Assumption Setting'!$C$202)*(1+'Assumption Setting'!$C$203)/'Timeline and FX'!AG8 -> 857.6227 | AH6: =(Payroll!AH76*'Assumption Setting'!$C$201+Payroll!AH75*'Assumption Setting'!$C$202)*(1+'Assumption Setting'!$C$203)/'Timeline and FX'!AH8 -> 0 | AI6: =(Payroll!AI76*'Assumption Setting'!$C$201+Payroll!AI75*'Assumption Setting'!$C$202)*(1+'Assumption Setting'!$C$203)/'Timeline and FX'!AI8 -> 1698.6684 | AJ6: =(Payroll!AJ76*'Assumption Setting'!$C$201+Payroll!AJ75*'Assumption Setting'!$C$202)*(1+'Assumption Setting'!$C$203)/'Timeline and FX'!AJ8 -> 0 | ... AN6: =(Payroll!AN76*'Assumption Setting'!$C$201+Payroll!AN75*'Assumption Setting'!$C$202)*(1+'Assumption Setting'!$C$203)/'Timeline and FX'!AN8 -> 0 | AO6: =SUM(AP6:BA6) -> 21889.776 | AP6: =(Payroll!AP76*'Assumption Setting'!$C$201+Payroll!AP75*'Assumption Setting'!$C$202)*(1+'Assumption Setting'!$C$203)/'Timeline and FX'!AP8 -> 13055.672 | AQ6: =(Payroll!AQ76*'Assumption Setting'!$C$201+Payroll!AQ75*'Assumption Setting'!$C$202)*(1+'Assumption Setting'!$C$203)/'Timeline and FX'!AQ8 -> 820.95031 | AR6: =(Payroll!AR76*'Assumption Setting'!$C$201+Payroll!AR75*'Assumption Setting'!$C$202)*(1+'Assumption Setting'!$C$203)/'Timeline and FX'!AR8 -> 816.97365 | AS6: =(Payroll!AS76*'Assumption Setting'!$C$201+Payroll!AS75*'Assumption Setting'!$C$202)*(1+'Assumption Setting'!$C$203)/'Timeline and FX'!AS8 -> 813.01625 | AT6: =(Payroll!AT76*'Assumption Setting'!$C$201+Payroll!AT75*'Assumption Setting'!$C$202)*(1+'Assumption Setting'!$C$203)/'Timeline and FX'!AT8 -> 809.07802 | AU6: =(Payroll!AU76*'Assumption Setting'!$C$201+Payroll!AU75*'Assumption Setting'!$C$202)*(1+'Assumption Setting'!$C$203)/'Timeline and FX'!AU8 -> 805.15887 | AV6: =(Payroll!AV76*'Assumption Setting'!$C$201+Payroll!AV75*'Assumption Setting'!$C$202)*(1+'Assumption Setting'!$C$203)/'Timeline and FX'!AV8 -> 1602.5174 | AW6: =(Payroll!AW76*'Assumption Setting'!$C$201+Payroll!AW75*'Assumption Setting'!$C$202)*(1+'Assumption Setting'!$C$203)/'Timeline and FX'!AW8 -> 797.37743 | ... BA6: =(Payroll!BA76*'Assumption Setting'!$C$201+Payroll!BA75*'Assumption Setting'!$C$202)*(1+'Assumption Setting'!$C$203)/'Timeline and FX'!BA8 -> 0 | BB6: =SUM(BC6:BN6) -> 26848.423 | BC6: =(Payroll!BC76*'Assumption Setting'!$C$201+Payroll!BC75*'Assumption Setting'!$C$202)*(1+'Assumption Setting'!$C$203)/'Timeline and FX'!BC8 -> 13974.685 | BD6: =(Payroll!BD76*'Assumption Setting'!$C$201+Payroll!BD75*'Assumption Setting'!$C$202)*(1+'Assumption Setting'!$C$203)/'Timeline and FX'!BD8 -> 1548.9628 | BE6: =(Payroll!BE76*'Assumption Setting'!$C$201+Payroll!BE75*'Assumption Setting'!$C$202)*(1+'Assumption Setting'!$C$203)/'Timeline and FX'!BE8 -> 1541.4597 | BF6: =(Payroll!BF76*'Assumption Setting'!$C$201+Payroll!BF75*'Assumption Setting'!$C$202)*(1+'Assumption Setting'!$C$203)/'Timeline and FX'!BF8 -> 0 | BG6: =(Payroll!BG76*'Assumption Setting'!$C$201+Payroll!BG75*'Assumption Setting'!$C$202)*(1+'Assumption Setting'!$C$203)/'Timeline and FX'!BG8 -> 1526.5623 | BH6: =(Payroll!BH76*'Assumption Setting'!$C$201+Payroll!BH75*'Assumption Setting'!$C$202)*(1+'Assumption Setting'!$C$203)/'Timeline and FX'!BH8 -> 1519.1677 | BI6: =(Payroll!BI76*'Assumption Setting'!$C$201+Payroll!BI75*'Assumption Setting'!$C$202)*(1+'Assumption Setting'!$C$203)/'Timeline and FX'!BI8 -> 2267.7133 | BJ6: =(Payroll!BJ76*'Assumption Setting'!$C$201+Payroll!BJ75*'Assumption Setting'!$C$202)*(1+'Assumption Setting'!$C$203)/'Timeline and FX'!BJ8 -> 0 | ... BN6: =(Payroll!BN76*'Assumption Setting'!$C$201+Payroll!BN75*'Assumption Setting'!$C$202)*(1+'Assumption Setting'!$C$203)/'Timeline and FX'!BN8 -> 0
A7: Cairo office fit out | B7: =SUM(C7:N7) -> 6796.1165 | C7: =IF(1='Assumption Setting'!$D$205,'Assumption Setting'!$C$205/'Timeline and FX'!C8,0) -> 6796.1165 | D7: =IF(2='Assumption Setting'!$D$205,'Assumption Setting'!$C$205/'Timeline and FX'!D8,0) -> 0 | E7: =IF(3='Assumption Setting'!$D$205,'Assumption Setting'!$C$205/'Timeline and FX'!E8,0) -> 0 | F7: =IF(4='Assumption Setting'!$D$205,'Assumption Setting'!$C$205/'Timeline and FX'!F8,0) -> 0 | G7: =IF(5='Assumption Setting'!$D$205,'Assumption Setting'!$C$205/'Timeline and FX'!G8,0) -> 0 | H7: =IF(6='Assumption Setting'!$D$205,'Assumption Setting'!$C$205/'Timeline and FX'!H8,0) -> 0 | I7: =IF(7='Assumption Setting'!$D$205,'Assumption Setting'!$C$205/'Timeline and FX'!I8,0) -> 0 | J7: =IF(8='Assumption Setting'!$D$205,'Assumption Setting'!$C$205/'Timeline and FX'!J8,0) -> 0 | K7: =IF(9='Assumption Setting'!$D$205,'Assumption Setting'!$C$205/'Timeline and FX'!K8,0) -> 0 | L7: =IF(10='Assumption Setting'!$D$205,'Assumption Setting'!$C$205/'Timeline and FX'!L8,0) -> 0 | M7: =IF(11='Assumption Setting'!$D$205,'Assumption Setting'!$C$205/'Timeline and FX'!M8,0) -> 0 | N7: =IF(12='Assumption Setting'!$D$205,'Assumption Setting'!$C$205/'Timeline and FX'!N8,0) -> 0 | O7: =SUM(P7:AA7) -> 0 | P7: =IF(13='Assumption Setting'!$D$205,'Assumption Setting'!$C$205/'Timeline and FX'!P8,0) -> 0 | Q7: =IF(14='Assumption Setting'!$D$205,'Assumption Setting'!$C$205/'Timeline and FX'!Q8,0) -> 0 | R7: =IF(15='Assumption Setting'!$D$205,'Assumption Setting'!$C$205/'Timeline and FX'!R8,0) -> 0 | S7: =IF(16='Assumption Setting'!$D$205,'Assumption Setting'!$C$205/'Timeline and FX'!S8,0) -> 0 | T7: =IF(17='Assumption Setting'!$D$205,'Assumption Setting'!$C$205/'Timeline and FX'!T8,0) -> 0 | U7: =IF(18='Assumption Setting'!$D$205,'Assumption Setting'!$C$205/'Timeline and FX'!U8,0) -> 0 | V7: =IF(19='Assumption Setting'!$D$205,'Assumption Setting'!$C$205/'Timeline and FX'!V8,0) -> 0 | W7: =IF(20='Assumption Setting'!$D$205,'Assumption Setting'!$C$205/'Timeline and FX'!W8,0) -> 0 | X7: =IF(21='Assumption Setting'!$D$205,'Assumption Setting'!$C$205/'Timeline and FX'!X8,0) -> 0 | Y7: =IF(22='Assumption Setting'!$D$205,'Assumption Setting'!$C$205/'Timeline and FX'!Y8,0) -> 0 | Z7: =IF(23='Assumption Setting'!$D$205,'Assumption Setting'!$C$205/'Timeline and FX'!Z8,0) -> 0 | AA7: =IF(24='Assumption Setting'!$D$205,'Assumption Setting'!$C$205/'Timeline and FX'!AA8,0) -> 0 | AB7: =SUM(AC7:AN7) -> 0 | AC7: =IF(25='Assumption Setting'!$D$205,'Assumption Setting'!$C$205/'Timeline and FX'!AC8,0) -> 0 | AD7: =IF(26='Assumption Setting'!$D$205,'Assumption Setting'!$C$205/'Timeline and FX'!AD8,0) -> 0 | AE7: =IF(27='Assumption Setting'!$D$205,'Assumption Setting'!$C$205/'Timeline and FX'!AE8,0) -> 0 | AF7: =IF(28='Assumption Setting'!$D$205,'Assumption Setting'!$C$205/'Timeline and FX'!AF8,0) -> 0 | AG7: =IF(29='Assumption Setting'!$D$205,'Assumption Setting'!$C$205/'Timeline and FX'!AG8,0) -> 0 | AH7: =IF(30='Assumption Setting'!$D$205,'Assumption Setting'!$C$205/'Timeline and FX'!AH8,0) -> 0 | AI7: =IF(31='Assumption Setting'!$D$205,'Assumption Setting'!$C$205/'Timeline and FX'!AI8,0) -> 0 | AJ7: =IF(32='Assumption Setting'!$D$205,'Assumption Setting'!$C$205/'Timeline and FX'!AJ8,0) -> 0 | AK7: =IF(33='Assumption Setting'!$D$205,'Assumption Setting'!$C$205/'Timeline and FX'!AK8,0) -> 0 | AL7: =IF(34='Assumption Setting'!$D$205,'Assumption Setting'!$C$205/'Timeline and FX'!AL8,0) -> 0 | AM7: =IF(35='Assumption Setting'!$D$205,'Assumption Setting'!$C$205/'Timeline and FX'!AM8,0) -> 0 | AN7: =IF(36='Assumption Setting'!$D$205,'Assumption Setting'!$C$205/'Timeline and FX'!AN8,0) -> 0 | AO7: =SUM(AP7:BA7) -> 0 | AP7: =IF(37='Assumption Setting'!$D$205,'Assumption Setting'!$C$205/'Timeline and FX'!AP8,0) -> 0 | AQ7: =IF(38='Assumption Setting'!$D$205,'Assumption Setting'!$C$205/'Timeline and FX'!AQ8,0) -> 0 | AR7: =IF(39='Assumption Setting'!$D$205,'Assumption Setting'!$C$205/'Timeline and FX'!AR8,0) -> 0 | AS7: =IF(40='Assumption Setting'!$D$205,'Assumption Setting'!$C$205/'Timeline and FX'!AS8,0) -> 0 | AT7: =IF(41='Assumption Setting'!$D$205,'Assumption Setting'!$C$205/'Timeline and FX'!AT8,0) -> 0 | AU7: =IF(42='Assumption Setting'!$D$205,'Assumption Setting'!$C$205/'Timeline and FX'!AU8,0) -> 0 | AV7: =IF(43='Assumption Setting'!$D$205,'Assumption Setting'!$C$205/'Timeline and FX'!AV8,0) -> 0 | AW7: =IF(44='Assumption Setting'!$D$205,'Assumption Setting'!$C$205/'Timeline and FX'!AW8,0) -> 0 | AX7: =IF(45='Assumption Setting'!$D$205,'Assumption Setting'!$C$205/'Timeline and FX'!AX8,0) -> 0 | AY7: =IF(46='Assumption Setting'!$D$205,'Assumption Setting'!$C$205/'Timeline and FX'!AY8,0) -> 0 | AZ7: =IF(47='Assumption Setting'!$D$205,'Assumption Setting'!$C$205/'Timeline and FX'!AZ8,0) -> 0 | BA7: =IF(48='Assumption Setting'!$D$205,'Assumption Setting'!$C$205/'Timeline and FX'!BA8,0) -> 0 | BB7: =SUM(BC7:BN7) -> 0 | BC7: =IF(49='Assumption Setting'!$D$205,'Assumption Setting'!$C$205/'Timeline and FX'!BC8,0) -> 0 | BD7: =IF(50='Assumption Setting'!$D$205,'Assumption Setting'!$C$205/'Timeline and FX'!BD8,0) -> 0 | BE7: =IF(51='Assumption Setting'!$D$205,'Assumption Setting'!$C$205/'Timeline and FX'!BE8,0) -> 0 | BF7: =IF(52='Assumption Setting'!$D$205,'Assumption Setting'!$C$205/'Timeline and FX'!BF8,0) -> 0 | BG7: =IF(53='Assumption Setting'!$D$205,'Assumption Setting'!$C$205/'Timeline and FX'!BG8,0) -> 0 | BH7: =IF(54='Assumption Setting'!$D$205,'Assumption Setting'!$C$205/'Timeline and FX'!BH8,0) -> 0 | BI7: =IF(55='Assumption Setting'!$D$205,'Assumption Setting'!$C$205/'Timeline and FX'!BI8,0) -> 0 | BJ7: =IF(56='Assumption Setting'!$D$205,'Assumption Setting'!$C$205/'Timeline and FX'!BJ8,0) -> 0 | BK7: =IF(57='Assumption Setting'!$D$205,'Assumption Setting'!$C$205/'Timeline and FX'!BK8,0) -> 0 | BL7: =IF(58='Assumption Setting'!$D$205,'Assumption Setting'!$C$205/'Timeline and FX'!BL8,0) -> 0 | BM7: =IF(59='Assumption Setting'!$D$205,'Assumption Setting'!$C$205/'Timeline and FX'!BM8,0) -> 0 | BN7: =IF(60='Assumption Setting'!$D$205,'Assumption Setting'!$C$205/'Timeline and FX'!BN8,0) -> 0
A8: Network, devices and security | B8: =SUM(C8:N8) -> 2912.6214 | C8: =IF(1='Assumption Setting'!$D$206,'Assumption Setting'!$C$206/'Timeline and FX'!C8,0) -> 2912.6214 | D8: =IF(2='Assumption Setting'!$D$206,'Assumption Setting'!$C$206/'Timeline and FX'!D8,0) -> 0 | E8: =IF(3='Assumption Setting'!$D$206,'Assumption Setting'!$C$206/'Timeline and FX'!E8,0) -> 0 | F8: =IF(4='Assumption Setting'!$D$206,'Assumption Setting'!$C$206/'Timeline and FX'!F8,0) -> 0 | G8: =IF(5='Assumption Setting'!$D$206,'Assumption Setting'!$C$206/'Timeline and FX'!G8,0) -> 0 | H8: =IF(6='Assumption Setting'!$D$206,'Assumption Setting'!$C$206/'Timeline and FX'!H8,0) -> 0 | I8: =IF(7='Assumption Setting'!$D$206,'Assumption Setting'!$C$206/'Timeline and FX'!I8,0) -> 0 | J8: =IF(8='Assumption Setting'!$D$206,'Assumption Setting'!$C$206/'Timeline and FX'!J8,0) -> 0 | K8: =IF(9='Assumption Setting'!$D$206,'Assumption Setting'!$C$206/'Timeline and FX'!K8,0) -> 0 | L8: =IF(10='Assumption Setting'!$D$206,'Assumption Setting'!$C$206/'Timeline and FX'!L8,0) -> 0 | M8: =IF(11='Assumption Setting'!$D$206,'Assumption Setting'!$C$206/'Timeline and FX'!M8,0) -> 0 | N8: =IF(12='Assumption Setting'!$D$206,'Assumption Setting'!$C$206/'Timeline and FX'!N8,0) -> 0 | O8: =SUM(P8:AA8) -> 0 | P8: =IF(13='Assumption Setting'!$D$206,'Assumption Setting'!$C$206/'Timeline and FX'!P8,0) -> 0 | Q8: =IF(14='Assumption Setting'!$D$206,'Assumption Setting'!$C$206/'Timeline and FX'!Q8,0) -> 0 | R8: =IF(15='Assumption Setting'!$D$206,'Assumption Setting'!$C$206/'Timeline and FX'!R8,0) -> 0 | S8: =IF(16='Assumption Setting'!$D$206,'Assumption Setting'!$C$206/'Timeline and FX'!S8,0) -> 0 | T8: =IF(17='Assumption Setting'!$D$206,'Assumption Setting'!$C$206/'Timeline and FX'!T8,0) -> 0 | U8: =IF(18='Assumption Setting'!$D$206,'Assumption Setting'!$C$206/'Timeline and FX'!U8,0) -> 0 | V8: =IF(19='Assumption Setting'!$D$206,'Assumption Setting'!$C$206/'Timeline and FX'!V8,0) -> 0 | W8: =IF(20='Assumption Setting'!$D$206,'Assumption Setting'!$C$206/'Timeline and FX'!W8,0) -> 0 | X8: =IF(21='Assumption Setting'!$D$206,'Assumption Setting'!$C$206/'Timeline and FX'!X8,0) -> 0 | Y8: =IF(22='Assumption Setting'!$D$206,'Assumption Setting'!$C$206/'Timeline and FX'!Y8,0) -> 0 | Z8: =IF(23='Assumption Setting'!$D$206,'Assumption Setting'!$C$206/'Timeline and FX'!Z8,0) -> 0 | AA8: =IF(24='Assumption Setting'!$D$206,'Assumption Setting'!$C$206/'Timeline and FX'!AA8,0) -> 0 | AB8: =SUM(AC8:AN8) -> 0 | AC8: =IF(25='Assumption Setting'!$D$206,'Assumption Setting'!$C$206/'Timeline and FX'!AC8,0) -> 0 | AD8: =IF(26='Assumption Setting'!$D$206,'Assumption Setting'!$C$206/'Timeline and FX'!AD8,0) -> 0 | AE8: =IF(27='Assumption Setting'!$D$206,'Assumption Setting'!$C$206/'Timeline and FX'!AE8,0) -> 0 | AF8: =IF(28='Assumption Setting'!$D$206,'Assumption Setting'!$C$206/'Timeline and FX'!AF8,0) -> 0 | AG8: =IF(29='Assumption Setting'!$D$206,'Assumption Setting'!$C$206/'Timeline and FX'!AG8,0) -> 0 | AH8: =IF(30='Assumption Setting'!$D$206,'Assumption Setting'!$C$206/'Timeline and FX'!AH8,0) -> 0 | AI8: =IF(31='Assumption Setting'!$D$206,'Assumption Setting'!$C$206/'Timeline and FX'!AI8,0) -> 0 | AJ8: =IF(32='Assumption Setting'!$D$206,'Assumption Setting'!$C$206/'Timeline and FX'!AJ8,0) -> 0 | AK8: =IF(33='Assumption Setting'!$D$206,'Assumption Setting'!$C$206/'Timeline and FX'!AK8,0) -> 0 | AL8: =IF(34='Assumption Setting'!$D$206,'Assumption Setting'!$C$206/'Timeline and FX'!AL8,0) -> 0 | AM8: =IF(35='Assumption Setting'!$D$206,'Assumption Setting'!$C$206/'Timeline and FX'!AM8,0) -> 0 | AN8: =IF(36='Assumption Setting'!$D$206,'Assumption Setting'!$C$206/'Timeline and FX'!AN8,0) -> 0 | AO8: =SUM(AP8:BA8) -> 0 | AP8: =IF(37='Assumption Setting'!$D$206,'Assumption Setting'!$C$206/'Timeline and FX'!AP8,0) -> 0 | AQ8: =IF(38='Assumption Setting'!$D$206,'Assumption Setting'!$C$206/'Timeline and FX'!AQ8,0) -> 0 | AR8: =IF(39='Assumption Setting'!$D$206,'Assumption Setting'!$C$206/'Timeline and FX'!AR8,0) -> 0 | AS8: =IF(40='Assumption Setting'!$D$206,'Assumption Setting'!$C$206/'Timeline and FX'!AS8,0) -> 0 | AT8: =IF(41='Assumption Setting'!$D$206,'Assumption Setting'!$C$206/'Timeline and FX'!AT8,0) -> 0 | AU8: =IF(42='Assumption Setting'!$D$206,'Assumption Setting'!$C$206/'Timeline and FX'!AU8,0) -> 0 | AV8: =IF(43='Assumption Setting'!$D$206,'Assumption Setting'!$C$206/'Timeline and FX'!AV8,0) -> 0 | AW8: =IF(44='Assumption Setting'!$D$206,'Assumption Setting'!$C$206/'Timeline and FX'!AW8,0) -> 0 | AX8: =IF(45='Assumption Setting'!$D$206,'Assumption Setting'!$C$206/'Timeline and FX'!AX8,0) -> 0 | AY8: =IF(46='Assumption Setting'!$D$206,'Assumption Setting'!$C$206/'Timeline and FX'!AY8,0) -> 0 | AZ8: =IF(47='Assumption Setting'!$D$206,'Assumption Setting'!$C$206/'Timeline and FX'!AZ8,0) -> 0 | BA8: =IF(48='Assumption Setting'!$D$206,'Assumption Setting'!$C$206/'Timeline and FX'!BA8,0) -> 0 | BB8: =SUM(BC8:BN8) -> 0 | BC8: =IF(49='Assumption Setting'!$D$206,'Assumption Setting'!$C$206/'Timeline and FX'!BC8,0) -> 0 | BD8: =IF(50='Assumption Setting'!$D$206,'Assumption Setting'!$C$206/'Timeline and FX'!BD8,0) -> 0 | BE8: =IF(51='Assumption Setting'!$D$206,'Assumption Setting'!$C$206/'Timeline and FX'!BE8,0) -> 0 | BF8: =IF(52='Assumption Setting'!$D$206,'Assumption Setting'!$C$206/'Timeline and FX'!BF8,0) -> 0 | BG8: =IF(53='Assumption Setting'!$D$206,'Assumption Setting'!$C$206/'Timeline and FX'!BG8,0) -> 0 | BH8: =IF(54='Assumption Setting'!$D$206,'Assumption Setting'!$C$206/'Timeline and FX'!BH8,0) -> 0 | BI8: =IF(55='Assumption Setting'!$D$206,'Assumption Setting'!$C$206/'Timeline and FX'!BI8,0) -> 0 | BJ8: =IF(56='Assumption Setting'!$D$206,'Assumption Setting'!$C$206/'Timeline and FX'!BJ8,0) -> 0 | BK8: =IF(57='Assumption Setting'!$D$206,'Assumption Setting'!$C$206/'Timeline and FX'!BK8,0) -> 0 | BL8: =IF(58='Assumption Setting'!$D$206,'Assumption Setting'!$C$206/'Timeline and FX'!BL8,0) -> 0 | BM8: =IF(59='Assumption Setting'!$D$206,'Assumption Setting'!$C$206/'Timeline and FX'!BM8,0) -> 0 | BN8: =IF(60='Assumption Setting'!$D$206,'Assumption Setting'!$C$206/'Timeline and FX'!BN8,0) -> 0
A9: POS demo and event kit | B9: =SUM(C9:N9) -> 3495.1456 | C9: =IF(1='Assumption Setting'!$D$208,'Assumption Setting'!$C$208/'Timeline and FX'!C8,0) -> 3495.1456 | D9: =IF(2='Assumption Setting'!$D$208,'Assumption Setting'!$C$208/'Timeline and FX'!D8,0) -> 0 | E9: =IF(3='Assumption Setting'!$D$208,'Assumption Setting'!$C$208/'Timeline and FX'!E8,0) -> 0 | F9: =IF(4='Assumption Setting'!$D$208,'Assumption Setting'!$C$208/'Timeline and FX'!F8,0) -> 0 | G9: =IF(5='Assumption Setting'!$D$208,'Assumption Setting'!$C$208/'Timeline and FX'!G8,0) -> 0 | H9: =IF(6='Assumption Setting'!$D$208,'Assumption Setting'!$C$208/'Timeline and FX'!H8,0) -> 0 | I9: =IF(7='Assumption Setting'!$D$208,'Assumption Setting'!$C$208/'Timeline and FX'!I8,0) -> 0 | J9: =IF(8='Assumption Setting'!$D$208,'Assumption Setting'!$C$208/'Timeline and FX'!J8,0) -> 0 | K9: =IF(9='Assumption Setting'!$D$208,'Assumption Setting'!$C$208/'Timeline and FX'!K8,0) -> 0 | L9: =IF(10='Assumption Setting'!$D$208,'Assumption Setting'!$C$208/'Timeline and FX'!L8,0) -> 0 | M9: =IF(11='Assumption Setting'!$D$208,'Assumption Setting'!$C$208/'Timeline and FX'!M8,0) -> 0 | N9: =IF(12='Assumption Setting'!$D$208,'Assumption Setting'!$C$208/'Timeline and FX'!N8,0) -> 0 | O9: =SUM(P9:AA9) -> 0 | P9: =IF(13='Assumption Setting'!$D$208,'Assumption Setting'!$C$208/'Timeline and FX'!P8,0) -> 0 | Q9: =IF(14='Assumption Setting'!$D$208,'Assumption Setting'!$C$208/'Timeline and FX'!Q8,0) -> 0 | R9: =IF(15='Assumption Setting'!$D$208,'Assumption Setting'!$C$208/'Timeline and FX'!R8,0) -> 0 | S9: =IF(16='Assumption Setting'!$D$208,'Assumption Setting'!$C$208/'Timeline and FX'!S8,0) -> 0 | T9: =IF(17='Assumption Setting'!$D$208,'Assumption Setting'!$C$208/'Timeline and FX'!T8,0) -> 0 | U9: =IF(18='Assumption Setting'!$D$208,'Assumption Setting'!$C$208/'Timeline and FX'!U8,0) -> 0 | V9: =IF(19='Assumption Setting'!$D$208,'Assumption Setting'!$C$208/'Timeline and FX'!V8,0) -> 0 | W9: =IF(20='Assumption Setting'!$D$208,'Assumption Setting'!$C$208/'Timeline and FX'!W8,0) -> 0 | X9: =IF(21='Assumption Setting'!$D$208,'Assumption Setting'!$C$208/'Timeline and FX'!X8,0) -> 0 | Y9: =IF(22='Assumption Setting'!$D$208,'Assumption Setting'!$C$208/'Timeline and FX'!Y8,0) -> 0 | Z9: =IF(23='Assumption Setting'!$D$208,'Assumption Setting'!$C$208/'Timeline and FX'!Z8,0) -> 0 | AA9: =IF(24='Assumption Setting'!$D$208,'Assumption Setting'!$C$208/'Timeline and FX'!AA8,0) -> 0 | AB9: =SUM(AC9:AN9) -> 0 | AC9: =IF(25='Assumption Setting'!$D$208,'Assumption Setting'!$C$208/'Timeline and FX'!AC8,0) -> 0 | AD9: =IF(26='Assumption Setting'!$D$208,'Assumption Setting'!$C$208/'Timeline and FX'!AD8,0) -> 0 | AE9: =IF(27='Assumption Setting'!$D$208,'Assumption Setting'!$C$208/'Timeline and FX'!AE8,0) -> 0 | AF9: =IF(28='Assumption Setting'!$D$208,'Assumption Setting'!$C$208/'Timeline and FX'!AF8,0) -> 0 | AG9: =IF(29='Assumption Setting'!$D$208,'Assumption Setting'!$C$208/'Timeline and FX'!AG8,0) -> 0 | AH9: =IF(30='Assumption Setting'!$D$208,'Assumption Setting'!$C$208/'Timeline and FX'!AH8,0) -> 0 | AI9: =IF(31='Assumption Setting'!$D$208,'Assumption Setting'!$C$208/'Timeline and FX'!AI8,0) -> 0 | AJ9: =IF(32='Assumption Setting'!$D$208,'Assumption Setting'!$C$208/'Timeline and FX'!AJ8,0) -> 0 | AK9: =IF(33='Assumption Setting'!$D$208,'Assumption Setting'!$C$208/'Timeline and FX'!AK8,0) -> 0 | AL9: =IF(34='Assumption Setting'!$D$208,'Assumption Setting'!$C$208/'Timeline and FX'!AL8,0) -> 0 | AM9: =IF(35='Assumption Setting'!$D$208,'Assumption Setting'!$C$208/'Timeline and FX'!AM8,0) -> 0 | AN9: =IF(36='Assumption Setting'!$D$208,'Assumption Setting'!$C$208/'Timeline and FX'!AN8,0) -> 0 | AO9: =SUM(AP9:BA9) -> 0 | AP9: =IF(37='Assumption Setting'!$D$208,'Assumption Setting'!$C$208/'Timeline and FX'!AP8,0) -> 0 | AQ9: =IF(38='Assumption Setting'!$D$208,'Assumption Setting'!$C$208/'Timeline and FX'!AQ8,0) -> 0 | AR9: =IF(39='Assumption Setting'!$D$208,'Assumption Setting'!$C$208/'Timeline and FX'!AR8,0) -> 0 | AS9: =IF(40='Assumption Setting'!$D$208,'Assumption Setting'!$C$208/'Timeline and FX'!AS8,0) -> 0 | AT9: =IF(41='Assumption Setting'!$D$208,'Assumption Setting'!$C$208/'Timeline and FX'!AT8,0) -> 0 | AU9: =IF(42='Assumption Setting'!$D$208,'Assumption Setting'!$C$208/'Timeline and FX'!AU8,0) -> 0 | AV9: =IF(43='Assumption Setting'!$D$208,'Assumption Setting'!$C$208/'Timeline and FX'!AV8,0) -> 0 | AW9: =IF(44='Assumption Setting'!$D$208,'Assumption Setting'!$C$208/'Timeline and FX'!AW8,0) -> 0 | AX9: =IF(45='Assumption Setting'!$D$208,'Assumption Setting'!$C$208/'Timeline and FX'!AX8,0) -> 0 | AY9: =IF(46='Assumption Setting'!$D$208,'Assumption Setting'!$C$208/'Timeline and FX'!AY8,0) -> 0 | AZ9: =IF(47='Assumption Setting'!$D$208,'Assumption Setting'!$C$208/'Timeline and FX'!AZ8,0) -> 0 | BA9: =IF(48='Assumption Setting'!$D$208,'Assumption Setting'!$C$208/'Timeline and FX'!BA8,0) -> 0 | BB9: =SUM(BC9:BN9) -> 0 | BC9: =IF(49='Assumption Setting'!$D$208,'Assumption Setting'!$C$208/'Timeline and FX'!BC8,0) -> 0 | BD9: =IF(50='Assumption Setting'!$D$208,'Assumption Setting'!$C$208/'Timeline and FX'!BD8,0) -> 0 | BE9: =IF(51='Assumption Setting'!$D$208,'Assumption Setting'!$C$208/'Timeline and FX'!BE8,0) -> 0 | BF9: =IF(52='Assumption Setting'!$D$208,'Assumption Setting'!$C$208/'Timeline and FX'!BF8,0) -> 0 | BG9: =IF(53='Assumption Setting'!$D$208,'Assumption Setting'!$C$208/'Timeline and FX'!BG8,0) -> 0 | BH9: =IF(54='Assumption Setting'!$D$208,'Assumption Setting'!$C$208/'Timeline and FX'!BH8,0) -> 0 | BI9: =IF(55='Assumption Setting'!$D$208,'Assumption Setting'!$C$208/'Timeline and FX'!BI8,0) -> 0 | BJ9: =IF(56='Assumption Setting'!$D$208,'Assumption Setting'!$C$208/'Timeline and FX'!BJ8,0) -> 0 | BK9: =IF(57='Assumption Setting'!$D$208,'Assumption Setting'!$C$208/'Timeline and FX'!BK8,0) -> 0 | BL9: =IF(58='Assumption Setting'!$D$208,'Assumption Setting'!$C$208/'Timeline and FX'!BL8,0) -> 0 | BM9: =IF(59='Assumption Setting'!$D$208,'Assumption Setting'!$C$208/'Timeline and FX'!BM8,0) -> 0 | BN9: =IF(60='Assumption Setting'!$D$208,'Assumption Setting'!$C$208/'Timeline and FX'!BN8,0) -> 0
A10: Studio and content production kit | B10: =SUM(C10:N10) -> 1538.3853 | C10: =IF(1='Assumption Setting'!$D$209,'Assumption Setting'!$C$209/'Timeline and FX'!C8,0) -> 0 | D10: =IF(2='Assumption Setting'!$D$209,'Assumption Setting'!$C$209/'Timeline and FX'!D8,0) -> 0 | E10: =IF(3='Assumption Setting'!$D$209,'Assumption Setting'!$C$209/'Timeline and FX'!E8,0) -> 1538.3853 | F10: =IF(4='Assumption Setting'!$D$209,'Assumption Setting'!$C$209/'Timeline and FX'!F8,0) -> 0 | G10: =IF(5='Assumption Setting'!$D$209,'Assumption Setting'!$C$209/'Timeline and FX'!G8,0) -> 0 | H10: =IF(6='Assumption Setting'!$D$209,'Assumption Setting'!$C$209/'Timeline and FX'!H8,0) -> 0 | I10: =IF(7='Assumption Setting'!$D$209,'Assumption Setting'!$C$209/'Timeline and FX'!I8,0) -> 0 | J10: =IF(8='Assumption Setting'!$D$209,'Assumption Setting'!$C$209/'Timeline and FX'!J8,0) -> 0 | K10: =IF(9='Assumption Setting'!$D$209,'Assumption Setting'!$C$209/'Timeline and FX'!K8,0) -> 0 | L10: =IF(10='Assumption Setting'!$D$209,'Assumption Setting'!$C$209/'Timeline and FX'!L8,0) -> 0 | M10: =IF(11='Assumption Setting'!$D$209,'Assumption Setting'!$C$209/'Timeline and FX'!M8,0) -> 0 | N10: =IF(12='Assumption Setting'!$D$209,'Assumption Setting'!$C$209/'Timeline and FX'!N8,0) -> 0 | O10: =SUM(P10:AA10) -> 0 | P10: =IF(13='Assumption Setting'!$D$209,'Assumption Setting'!$C$209/'Timeline and FX'!P8,0) -> 0 | Q10: =IF(14='Assumption Setting'!$D$209,'Assumption Setting'!$C$209/'Timeline and FX'!Q8,0) -> 0 | R10: =IF(15='Assumption Setting'!$D$209,'Assumption Setting'!$C$209/'Timeline and FX'!R8,0) -> 0 | S10: =IF(16='Assumption Setting'!$D$209,'Assumption Setting'!$C$209/'Timeline and FX'!S8,0) -> 0 | T10: =IF(17='Assumption Setting'!$D$209,'Assumption Setting'!$C$209/'Timeline and FX'!T8,0) -> 0 | U10: =IF(18='Assumption Setting'!$D$209,'Assumption Setting'!$C$209/'Timeline and FX'!U8,0) -> 0 | V10: =IF(19='Assumption Setting'!$D$209,'Assumption Setting'!$C$209/'Timeline and FX'!V8,0) -> 0 | W10: =IF(20='Assumption Setting'!$D$209,'Assumption Setting'!$C$209/'Timeline and FX'!W8,0) -> 0 | X10: =IF(21='Assumption Setting'!$D$209,'Assumption Setting'!$C$209/'Timeline and FX'!X8,0) -> 0 | Y10: =IF(22='Assumption Setting'!$D$209,'Assumption Setting'!$C$209/'Timeline and FX'!Y8,0) -> 0 | Z10: =IF(23='Assumption Setting'!$D$209,'Assumption Setting'!$C$209/'Timeline and FX'!Z8,0) -> 0 | AA10: =IF(24='Assumption Setting'!$D$209,'Assumption Setting'!$C$209/'Timeline and FX'!AA8,0) -> 0 | AB10: =SUM(AC10:AN10) -> 0 | AC10: =IF(25='Assumption Setting'!$D$209,'Assumption Setting'!$C$209/'Timeline and FX'!AC8,0) -> 0 | AD10: =IF(26='Assumption Setting'!$D$209,'Assumption Setting'!$C$209/'Timeline and FX'!AD8,0) -> 0 | AE10: =IF(27='Assumption Setting'!$D$209,'Assumption Setting'!$C$209/'Timeline and FX'!AE8,0) -> 0 | AF10: =IF(28='Assumption Setting'!$D$209,'Assumption Setting'!$C$209/'Timeline and FX'!AF8,0) -> 0 | AG10: =IF(29='Assumption Setting'!$D$209,'Assumption Setting'!$C$209/'Timeline and FX'!AG8,0) -> 0 | AH10: =IF(30='Assumption Setting'!$D$209,'Assumption Setting'!$C$209/'Timeline and FX'!AH8,0) -> 0 | AI10: =IF(31='Assumption Setting'!$D$209,'Assumption Setting'!$C$209/'Timeline and FX'!AI8,0) -> 0 | AJ10: =IF(32='Assumption Setting'!$D$209,'Assumption Setting'!$C$209/'Timeline and FX'!AJ8,0) -> 0 | AK10: =IF(33='Assumption Setting'!$D$209,'Assumption Setting'!$C$209/'Timeline and FX'!AK8,0) -> 0 | AL10: =IF(34='Assumption Setting'!$D$209,'Assumption Setting'!$C$209/'Timeline and FX'!AL8,0) -> 0 | AM10: =IF(35='Assumption Setting'!$D$209,'Assumption Setting'!$C$209/'Timeline and FX'!AM8,0) -> 0 | AN10: =IF(36='Assumption Setting'!$D$209,'Assumption Setting'!$C$209/'Timeline and FX'!AN8,0) -> 0 | AO10: =SUM(AP10:BA10) -> 0 | AP10: =IF(37='Assumption Setting'!$D$209,'Assumption Setting'!$C$209/'Timeline and FX'!AP8,0) -> 0 | AQ10: =IF(38='Assumption Setting'!$D$209,'Assumption Setting'!$C$209/'Timeline and FX'!AQ8,0) -> 0 | AR10: =IF(39='Assumption Setting'!$D$209,'Assumption Setting'!$C$209/'Timeline and FX'!AR8,0) -> 0 | AS10: =IF(40='Assumption Setting'!$D$209,'Assumption Setting'!$C$209/'Timeline and FX'!AS8,0) -> 0 | AT10: =IF(41='Assumption Setting'!$D$209,'Assumption Setting'!$C$209/'Timeline and FX'!AT8,0) -> 0 | AU10: =IF(42='Assumption Setting'!$D$209,'Assumption Setting'!$C$209/'Timeline and FX'!AU8,0) -> 0 | AV10: =IF(43='Assumption Setting'!$D$209,'Assumption Setting'!$C$209/'Timeline and FX'!AV8,0) -> 0 | AW10: =IF(44='Assumption Setting'!$D$209,'Assumption Setting'!$C$209/'Timeline and FX'!AW8,0) -> 0 | AX10: =IF(45='Assumption Setting'!$D$209,'Assumption Setting'!$C$209/'Timeline and FX'!AX8,0) -> 0 | AY10: =IF(46='Assumption Setting'!$D$209,'Assumption Setting'!$C$209/'Timeline and FX'!AY8,0) -> 0 | AZ10: =IF(47='Assumption Setting'!$D$209,'Assumption Setting'!$C$209/'Timeline and FX'!AZ8,0) -> 0 | BA10: =IF(48='Assumption Setting'!$D$209,'Assumption Setting'!$C$209/'Timeline and FX'!BA8,0) -> 0 | BB10: =SUM(BC10:BN10) -> 0 | BC10: =IF(49='Assumption Setting'!$D$209,'Assumption Setting'!$C$209/'Timeline and FX'!BC8,0) -> 0 | BD10: =IF(50='Assumption Setting'!$D$209,'Assumption Setting'!$C$209/'Timeline and FX'!BD8,0) -> 0 | BE10: =IF(51='Assumption Setting'!$D$209,'Assumption Setting'!$C$209/'Timeline and FX'!BE8,0) -> 0 | BF10: =IF(52='Assumption Setting'!$D$209,'Assumption Setting'!$C$209/'Timeline and FX'!BF8,0) -> 0 | BG10: =IF(53='Assumption Setting'!$D$209,'Assumption Setting'!$C$209/'Timeline and FX'!BG8,0) -> 0 | BH10: =IF(54='Assumption Setting'!$D$209,'Assumption Setting'!$C$209/'Timeline and FX'!BH8,0) -> 0 | BI10: =IF(55='Assumption Setting'!$D$209,'Assumption Setting'!$C$209/'Timeline and FX'!BI8,0) -> 0 | BJ10: =IF(56='Assumption Setting'!$D$209,'Assumption Setting'!$C$209/'Timeline and FX'!BJ8,0) -> 0 | BK10: =IF(57='Assumption Setting'!$D$209,'Assumption Setting'!$C$209/'Timeline and FX'!BK8,0) -> 0 | BL10: =IF(58='Assumption Setting'!$D$209,'Assumption Setting'!$C$209/'Timeline and FX'!BL8,0) -> 0 | BM10: =IF(59='Assumption Setting'!$D$209,'Assumption Setting'!$C$209/'Timeline and FX'!BM8,0) -> 0 | BN10: =IF(60='Assumption Setting'!$D$209,'Assumption Setting'!$C$209/'Timeline and FX'!BN8,0) -> 0
